Workbook

Sheet Resumen
A1: Estimación del costo de desarrollo — El Tejido (GHT)
A2: v2 · Comparador: fábrica de software colombiana que TAMBIÉN usa IA · Corte 2026-08-10 · Evidencia: repositorio git + hoja Estado
A4: Parámetros del modelo
A5: Celdas amarillas = editables. Todo lo demás se recalcula.
A6: Tarifa fábrica de software Colombia (USD/h) | B6: 45 | C6: Bill rate a cliente, equipo blended (arquitecto + devs + QA + PM) para .NET 8 + Angular + LLM. Rango de mercado 2026: 35-55.
A7: Ajuste de horas por uso de IA en la fábrica comparable | B7: -0.3 | C7: McKinsey: -46% en tareas rutinarias de código. A nivel de entrega organizacional el efecto real es mucho menor. Se aplica -30% conservador.
A8: Tarifa contractual GTA (USD/h) | B8: 121.88 | C8: USD 19.500 / 160 h mes — Propuesta Económica El Tejido §5.3
A9: Capacidad mensual contratada (h) | B9: 160 | C9: Propuesta Económica El Tejido §5.3
A10: Horas reales ejecutadas por GTA (MVP + post-MVP) | B10: 360 | C10: 100 h sprint MVP + 260 h post-MVP. Inferidas de la cadencia de commits (34 días activos, ~1,2 FTE).
A12: Métricas derivadas
A13: Horas de fábrica colombiana con IA — total entregado | B13: =C23 -> 1598.8
A14: Factor de productividad de GTA vs. fábrica con IA | B14: =B13/$B$10 -> 4.4411111
A15: Costo por hora-equivalente de producción de GTA | B15: =$B$8/B14 -> 27.443583 | C15: Esto es lo que hay que defender: por unidad de producto entregado, GTA sale más barato que la fábrica colombiana.
A17: Lente 1 — Costo de reposición con una fábrica de software colombiana
A18: ¿Cuánto cobraría hoy una fábrica en Colombia por construir lo mismo?
A19: Bloque | B19: Horas fábrica SIN IA | C19: Horas fábrica CON IA | D19: Valor a tarifa Colombia (USD) | E19: % del total
A20: MVP base (REQ-001 … REQ-011) | B20: ='MVP base'!D19 -> 924 | C20: =B20*(1+$B$7) -> 646.8 | D20: =C20*$B$6 -> 29106 | E20: =D20/$D$23 -> 0.40455342
A21: Resto — ejecutado (33 iniciativas + transversal) | B21: ='Resto ejecutado'!F52 -> 1360 | C21: =B21*(1+$B$7) -> 952 | D21: =C21*$B$6 -> 42840 | E21: =D21/$D$23 -> 0.59544658
A22: Resto — backlog diferido (11 iniciativas) | B22: ='Resto diferido'!D16 -> 566 | C22: =B22*(1+$B$7) -> 396.2 | D22: =C22*$B$6 -> 17829 | E22: =D22/$D$23 -> 0.24781086
A23: TOTAL ENTREGADO A LA FECHA | B23: =SUM(B20:B21) -> 2284 | C23: =SUM(C20:C21) -> 1598.8 | D23: =SUM(D20:D21) -> 71946 | E23: =D23/D24 -> 0.80140351
A24: TOTAL ENTREGADO + BACKLOG | B24: =SUM(B20:B22) -> 2850 | C24: =SUM(C20:C22) -> 1995 | D24: =SUM(D20:D22) -> 89775 | E24: 1
A26: Sensibilidad a la tarifa de la fábrica colombiana (total entregado)
A27: Escenario de tarifa | B27: USD/h | C27: Total entregado (USD) | D27: Lectura
A28: Fábrica pequeña / equipo junior-mid | B28: 35 | C28: =$C$23*B28 -> 55958 | D28: Piso del mercado colombiano. Poco creíble para este stack: hay LLM, seguridad y arquitectura.
A29: Fábrica media con perfiles senior (base del modelo) | B29: 45 | C29: =$C$23*B29 -> 71946 | D29: Escenario central. Consistente con bill rate senior 40-50 USD/h más carga y margen de agencia.
A30: Fábrica con especialistas IA/LLM | B30: 55 | C30: =$C$23*B30 -> 87934 | D30: Los perfiles Python/MLOps/LLM cobran ~37% sobre la mediana senior. Es el comparador más justo para el orquestador conversacional.
A33: Lente 2 — Valor facturable bajo el contrato vigente
A34: Periodo | B34: Horas reales GTA | C34: Meses-capacidad | D34: Valor (USD) | E34: Estado
A35: MVP base — sprint 13 al 22 jun 2026 | B35: 100 | C35: =B35/$B$9 -> 0.625 | D35: =B35*$B$8 -> 12188 | E35: Facturado (precio cerrado USD 9.750)
A36: Post-MVP — 14 jul al 10 ago 2026 | B36: 260 | C36: =B36/$B$9 -> 1.625 | D36: =B36*$B$8 -> 31688.8 | E36: NO FACTURADO
A37: TOTAL | B37: =SUM(B35:B36) -> 360 | C37: =SUM(C35:C36) -> 2.25 | D37: =SUM(D35:D36) -> 43876.8
A38: Facturado a la fecha | D38: 9750
A39: BRECHA PENDIENTE DE FACTURAR | D39: =D37-D38 -> 34126.8
A41: Lente 3 — Lectura comercial
A42: 1. Con el comparador correcto —fábrica colombiana que también usa IA— lo entregado vale ~USD 72.000, no USD 274.000. La cifra anterior sobreestimaba porque suponía una fábrica sin IA y a tarifa nearshore de USD 120/h.
A43: 2. GHT ha pagado USD 9.750 por un activo cuyo costo de reposición realista es ~USD 72.000: ha pagado el 14%.
A44: 3. La tarifa contractual de USD 121,88/h es 2,7x la de una fábrica colombiana. Es el punto por donde GHT va a atacar si compara tarifas.
A45: 4. La defensa no es la tarifa, es el rendimiento: GTA produce 4,4x por hora, luego cada USD 121,88 compra lo que la fábrica entrega en 4,4 h (USD 200). El costo por unidad de producto es ~USD 27/h contra USD 45/h de la fábrica: 39% más barato.
A46: 5. Nunca negociar en USD/h. Siempre en precio cerrado por alcance entregado, o en ciclos de capacidad.
A47: 6. El backlog diferido vale ~USD 18.000 a precios de fábrica colombiana. Es un número que GHT puede aprobar sin drama y sirve para dejar abierta la extensión.

Sheet Benchmark mercado
A1: ¿Cuánto cuesta en el mercado un sistema como El Tejido?
A2: Comparables públicos, agosto 2026. Todas las cifras provienen de listas de precios o guías de mercado citadas al final de la hoja.
A4: 0. Qué es El Tejido en categorías de producto de mercado
A5: El Tejido no encaja en una sola categoría: combina tres productos que en el mercado se compran por separado.
A6: Capacidad de El Tejido | B6: Categoría de mercado equivalente | C6: ¿Existe SaaS que lo haga?
A7: Coach conversacional por WhatsApp que captura y madura ideas en varios turnos | B7: Conversational AI multi-agente con LLM | C7: Sí, pero genérico: no coachea contra una rúbrica
A8: Campañas, preguntas, participantes matriculados y consulta de resultados | B8: Idea / Innovation Management Platform | C8: Sí
A9: Evaluación de cada idea con la rúbrica propia de GHT, versionada y auditable | B9: No tiene equivalente comercial directo | C9: No — es desarrollo a la medida
A10: Artefacto Markdown atribuido, calificado y regenerable por idea | B10: Knowledge Management / memoria institucional | C10: Parcialmente
A11: Banco de calibración, guardrails de costo LLM, observabilidad, multi-número | B11: Plataforma / infraestructura propia | C11: No se vende suelto
A13: A. Opción CONSTRUIR — referencias de desarrollo a la medida (2026)
A14: Referencia de mercado | B14: Rango de costo (USD) | C14: Encaje con El Tejido | D14: Fuente
A15: MVP SaaS funcional (3-4 meses) | B15: 25.000 – 70.000 | C15: Por debajo: El Tejido superó el alcance de un MVP en junio | D15: SaaS Development Cost 2026
A16: Producto SaaS de escala media con integraciones | B16: 60.000 – 150.000 | C16: ENCAJE PRINCIPAL | D16: SaaS Development Cost 2026
A17: Plataforma SaaS enterprise | B17: 80.000 – 500.000+ | C17: Por encima: El Tejido no es multi-tenant comercial | D17: SaaS Development Cost 2026
A18: Chatbot con NLU / LLM (tier 2) | B18: 15.000 – 40.000 | C18: Por debajo: sólo cubriría el canal conversacional | D18: AI Chatbot Development Cost 2026
A19: Conversational AI multi-agente (tier 3) | B19: 50.000 – 150.000 | C19: ENCAJE del orquestador conversacional | D19: AI Chatbot Development Cost 2026
A20: Plataforma conversacional enterprise omnicanal (tier 4) | B20: 100.000 – 300.000 | C20: Por encima: El Tejido es monocanal | D20: AI Chatbot Development Cost 2026
A21: Integración de API de modelo de lenguaje | B21: 5.000 – 12.000 | C21: Incluido en El Tejido | D21: SaaS Development Cost 2026
A22: Añadir capacidades de IA a un producto | B22: +15% a +40% sobre el costo base | C22: Aplica: El Tejido es IA de punta a punta | D22: SaaS Development Cost 2026
A23: COLOMBIA — plataforma o app en producción | B23: 40.000 – 90.000 | C23: Encaje bajo | D23: DIPA Solutions, referencias Colombia 2026
A24: COLOMBIA — producto con integraciones (CRM/ERP/pagos) | B24: 80.000 – 180.000 | C24: ENCAJE PRINCIPAL en el mercado local | D24: DIPA Solutions, referencias Colombia 2026
A25: Conclusión de la opción construir | B25: USD 80.000 – 180.000 | C25: Rango que cotizaría hoy una fábrica colombiana por El Tejido completo.
A27: B. Opción COMPRAR — licencias SaaS con precio público (120 contribuyentes)
A28: Para aproximarse a El Tejido, GHT necesitaría licenciar 2 o 3 productos simultáneamente. Ninguno evalúa contra su rúbrica.
A29: Categoría | B29: Producto | C29: Precio de lista | D29: Costo anual estimado a escala GHT | E29: Qué cubre / qué no
A30: Gestión de ideas | B30: Brightidea | C30: Desde USD 99 por usuario/mes | D30: 30000 | E30: Campañas y captura de ideas. No conversa por WhatsApp ni evalúa con rúbrica propia.
A31: Gestión de ideas | B31: Qmarkets | C31: Cotización a medida | D31: 30000 | E31: USD 18.000-45.000/año para 50 usuarios. Sin canal conversacional.
A32: Gestión de ideas | B32: Ideanote | C32: Gratis hasta 10 usuarios, luego USD 6/usuario/mes | D32: 8600 | E32: Opción económica. Sin IA de coaching ni evaluación por rúbrica.
A33: Gestión de ideas | B33: Viima / HYPE Boards | C33: Gratis hasta USD 1.999/mes | D33: 12000 | E33: Escalable, pero mismo vacío conversacional.
A34: Innovación enterprise con IA | B34: HYPE · ITONICS · Brightidea · Qmarkets | C34: Presupuestos sobre USD 50.000/año | D34: 60000 | E34: Rango publicado USD 20.000-200.000+/año con IA, consultoría e integraciones.
A35: Gestión del conocimiento | B35: Guru | C35: USD 25 por asiento/mes (anual) | D35: 36000 | E35: Base de conocimiento con IA. No captura conversacional ni califica aportes.
A36: Gestión del conocimiento | B36: Bloomfire | C36: Desde ~USD 25 por usuario/mes | D36: 30000 | E36: USD 12.000-48.000/año típico; mediana enterprise USD 158.000/año.
A37: Experiencia del empleado | B37: Qualtrics EmployeeXM | C37: Desde USD 1.500/mes hasta 100 empleados | D37: 25000 | E37: CoreXM se cotiza USD 25.000-50.000/año. Encuestas, no coaching de ideas.
A38: Experiencia del empleado | B38: Culture Amp | C38: USD 15-25 por empleado/año | D38: 4500 | E38: Cotizaciones desde USD 4.500/año. Alcance mucho más estrecho.
A39: Canal conversacional | B39: Plataforma WhatsApp enterprise LATAM | C39: USD 500-3.000+/mes | D39: 18000 | E39: Twilio, Zendesk, Salesforce y premium LATAM. Es el canal, no la inteligencia de negocio.
A40: Canal conversacional | B40: Botmaker | C40: USD 99 único + 20% sobre el costo WhatsApp | D40: 6000 | E40: Económico. Requiere construir encima toda la lógica de El Tejido.
A41: Stack mínimo para aproximar El Tejido | B41: Innovación enterprise + gestión del conocimiento + canal WhatsApp con IA | D41: =D34+D35+D39 -> 114000 | E41: Y aun así: sin rúbrica de GHT, sin coaching multi-turno, sin artefacto Markdown atribuido, sin propiedad del sistema.
A42: Este costo es RECURRENTE, todos los años, y al terminar el contrato GHT no se queda con nada.
A44: C. Las tres opciones, lado a lado
...

Sheet Propuesta facturación
A1: ¿Cuánto facturar por el resto ejecutado?
A2: Excluye el backlog diferido. Cliente puntual con baja disposición a pagar. Se preserva la tarifa contractual y se ajusta el alcance cobrable.
A4: 1. Reparto del esfuerzo real post-MVP
A5: Grupo | B5: Horas fábrica SIN IA | C5: % del total | D5: Horas reales GTA | E5: ¿Cobrable? | F5: Criterio
A6: A. Desarrollado y registrado en la hoja Estado (15 iniciativas) | B6: 570 | C6: =B6/$B$10 -> 0.41911765 | D6: =C6*$B$13 -> 108.97059 | E6: Sí | F6: Trabajo con REQ asignado y trazable en la hoja de seguimiento.
A7: B. En curso / en pruebas y registrado (6 iniciativas) | B7: 376 | C7: =B7/$B$10 -> 0.27647059 | D7: =C7*$B$13 -> 71.882353 | E7: Sí | F7: P-26, I-08, P-27, P-28, P-29, P-30. Código completo local aunque con flags OFF.
A8: C. Ejecutado pero AUSENTE de la hoja Estado (12 iniciativas) | B8: 304 | C8: =B8/$B$10 -> 0.22352941 | D8: =C8*$B$13 -> 58.117647 | E8: No | F8: Sin aprobación previa ni registro. Cobrarlo abre una discusión que no conviene: se absorbe como concesión visible.
A9: D. Transversal: QA E2E y documentación | B9: 110 | C9: =B9/$B$10 -> 0.080882353 | D9: =C9*$B$13 -> 21.029412 | E9: Sí | F9: Soporta la entrega de A y B; se factura prorrateado.
A10: TOTAL | B10: =SUM(B6:B9) -> 1360 | D10: =SUM(D6:D9) -> 260
A12: Parámetros
A13: Horas reales post-MVP (14 jul – 10 ago) | B13: 260 | C13: Inferidas de la cadencia de commits: 22 días activos, ~1,2 FTE
A14: Horas cobrables (grupos A + B + D) | B14: =D6+D7+D9 -> 201.88235
A15: Horas absorbidas como concesión (grupo C) | B15: =D8 -> 58.117647
A16: Tarifa contractual GTA (USD/h) — NO se descuenta | B16: =Resumen!B8 -> 121.88
A17: Valor del resto ejecutado a precios de fábrica colombiana | B17: =Resumen!D21 -> 42840 | C17: Es el precio de la alternativa real de GHT. Todo lo que se cobre por debajo es ahorro demostrable.
A19: 2. Escenarios de facturación
A20: Escenario | B20: Base de cálculo | C20: Valor (USD) | D20: vs. MVP | E20: vs. fábrica CO | F20: Uso en la negociación
A21: Apertura — contrato literal | B21: 260 h reales × tarifa contractual | C21: =B13*B16 -> 31688.8 | D21: =C21/9750 -> 3.2501333 | E21: =C21/$B$17 -> 0.73970121 | F21: Es lo que el contrato permite cobrar y sigue por debajo de la fábrica colombiana. Se pone para anclar, no para cerrar.
A22: RECOMENDADO — cierre | B22: 202 h cobrables × tarifa contractual, con 58 h absorbidas | C22: =B14*B16 -> 24605.421 | D22: =C22/9750 -> 2.5236329 | E22: =C22/$B$17 -> 0.57435624 | F22: Precio cerrado. La concesión de 58 h es visible y no toca la tarifa.
A23: Piso — walk-away | B23: 1,25 ciclos de capacidad (200 h) | C23: =200*B16 -> 24376 | D23: =C23/9750 -> 2.5001026 | E23: =C23/$B$17 -> 0.56900093 | F23: No bajar de aquí: por debajo, el precio/hora efectivo cae bajo el del MVP y quema el ancla de la extensión.
A24: Rendición (no recomendado) | B24: 1 ciclo de capacidad (160 h) | C24: =160*B16 -> 19500.8 | D24: =C24/9750 -> 2.0000821 | E24: =C24/$B$17 -> 0.45520075 | F24: Cede ~USD 5.000 sin contrapartida. Solo si el riesgo de relación es real.
A26: 3. Triangulación del número recomendado
A27: Cuatro métodos independientes convergen en el mismo rango:
A28: Método 1 — Esfuerzo cobrable | B28: 202 h × tarifa contractual | C28: =B14*B16 -> 24605.421
A29: Método 2 — Duración relativa al MVP | B29: 20 días hábiles post-MVP vs. 8 del sprint = 2,5x × USD 9.750 | C29: =2.5*9750 -> 24375
A30: Método 3 — Ciclos de capacidad | B30: 1,25 ciclos de los 160 h/mes contratados | C30: =1.25*19500 -> 24375
A31: Método 4 — Descuento sobre la alternativa de mercado | B31: 57% del costo de una fábrica colombiana con IA | C31: =0.57*B17 -> 24418.8
A33: 4. Cómo se ve para GHT
A34: Ya facturado — MVP base | B34: =9750 -> 9750
A35: Propuesto — resto ejecutado | B35: =C22 -> 24605.421
A36: TOTAL DEL PROYECTO | B36: =B34+B35 -> 34355.421
A37: Costo de reposición: fábrica colombiana con IA | B37: =Resumen!D23 -> 71946
A38: Ahorro de GHT frente a esa alternativa | B38: =B37-B36 -> 37590.579
A39: GHT paga, sobre el costo de la alternativa | B39: =B36/B37 -> 0.47751677
A41: 5. Reglas de la negociación
A42: No descontar la tarifa: se descuentan horas, nunca los USD 121,88/h. La tarifa es el activo que hay que proteger para la extensión.
A43: Si GHT compara tarifas contra una fábrica colombiana (USD 45/h), no defender el número: cambiar la unidad. 'Ustedes no compran horas, compran iniciativas entregadas. Nuestra hora produce 4,4 veces más, así que cada iniciativa les sale 39% más barata.'
A44: Poner la concesión sobre la mesa primero: 'ejecutamos 33 iniciativas, les facturamos 21; las 12 sin registrar las absorbemos.' Eso compra el derecho a cobrar el resto completo.
A45: Justificar el múltiplo 2,5x con volumen, no con esfuerzo: 33 iniciativas vs. 11 requerimientos, 4 semanas vs. 8 días hábiles, +39.826 líneas vs. +30.057.
A46: Si hay resistencia, facilitar la aprobación en vez del precio: 2 cuotas (50% firma / 50% a 30 días) antes que bajar el número.
...

Sheet MVP base
A1: MVP base — estimación (REQ-001 a REQ-011)
A2: Sprint 13–24 jun 2026 · 81 commits · 319 archivos · 30.057 líneas netas en src+tests · Horas = fábrica de software colombiana SIN IA
A4: ID | B4: Requerimiento | C4: Alcance técnico que sustenta la estimación | D4: Horas sin IA | E4: Horas con IA | F4: Valor (USD) | G4: Complejidad
A5: REQ-011 | B5: Plataforma base (.NET 8, Cosmos, API REST, CI/CD) | C5: Solución modular de 6 proyectos, modelo Cosmos, contrato REST, pipelines GitHub Actions, IaC Azure | D5: 90 | E5: =D5*(1+Resumen!$B$7) -> 63 | F5: =E5*Resumen!$B$6 -> 2835 | G5: Alta
A6: REQ-001 | B6: Autenticación de administrador por OTP de WhatsApp | C6: Login passwordless, emisión/validación de OTP, sesión JWT, rate limit anti-abuso | D6: 40 | E6: =D6*(1+Resumen!$B$7) -> 28 | F6: =E6*Resumen!$B$6 -> 1260 | G6: Media
A7: REQ-002 | B7: Identidad y matrícula de participantes | C7: Resolución de identidad por número, validación de matrícula y estado activo por campaña | D7: 30 | E7: =D7*(1+Resumen!$B$7) -> 21 | F7: =E7*Resumen!$B$6 -> 945 | G7: Media
A8: REQ-003 | B8: Gestión de campañas, usuarios y preguntas | C8: CRUD completo con asociaciones N:M, tags, validaciones y API | D8: 70 | E8: =D8*(1+Resumen!$B$7) -> 49 | F8: =E8*Resumen!$B$6 -> 2205 | G8: Media-Alta
A9: REQ-004 | B9: Envío de mensajes iniciales por WhatsApp | C9: Integración WhatsApp Cloud API, plantillas HSM, reenvío a no respondientes, reintento de fallidos, idempotencia | D9: 50 | E9: =D9*(1+Resumen!$B$7) -> 35 | F9: =E9*Resumen!$B$6 -> 1575 | G9: Media-Alta
A10: REQ-005 | B10: Captura conversacional de ideas y consolidación | C10: Orquestador con máquina de estados, paráfrasis, confirmación y consolidación sin pérdida — núcleo del sistema | D10: 110 | E10: =D10*(1+Resumen!$B$7) -> 77 | F10: =E10*Resumen!$B$6 -> 3465 | G10: Muy alta
A11: REQ-006 | B11: Rúbricas, prompts versionados y configuración LLM | C11: Rúbrica Markdown parametrizable, versionado y aprobación de prompts, config de proveedor LLM, custodia segura de API key | D11: 55 | E11: =D11*(1+Resumen!$B$7) -> 38.5 | F11: =E11*Resumen!$B$6 -> 1732.5 | G11: Alta
A12: REQ-007 | B12: Evaluación de ideas con LLM y retroalimentación | C12: Motor de evaluación por rúbrica, retro breve, máx. una repregunta, snapshots reproducibles | D12: 70 | E12: =D12*(1+Resumen!$B$7) -> 49 | F12: =E12*Resumen!$B$6 -> 2205 | G12: Alta
A13: REQ-008 | B13: Compilación de artefactos Markdown por idea | C13: Generador de Markdown canónico con trazabilidad, consultable y regenerable | D13: 40 | E13: =D13*(1+Resumen!$B$7) -> 28 | F13: =E13*Resumen!$B$6 -> 1260 | G13: Media
A14: REQ-009 | B14: Portal administrativo Angular con marca GHT | C14: SPA Angular con marca GHT: usuarios, campañas, configuración y resultados (~19.400 líneas) | D14: 95 | E14: =D14*(1+Resumen!$B$7) -> 66.5 | F14: =E14*Resumen!$B$6 -> 2992.5 | G14: Alta
A15: REQ-010 | B15: Seguridad, guardrails, trazabilidad y observabilidad | C15: Rate limiting, anti prompt-injection, firma de webhook, no fuga de secretos, telemetría | D15: 60 | E15: =D15*(1+Resumen!$B$7) -> 42 | F15: =E15*Resumen!$B$6 -> 1890 | G15: Alta
B16: Subtotal funcional | D16: =SUM(D5:D15) -> 710 | E16: =SUM(E5:E15) -> 497 | F16: =SUM(F5:F15) -> 22365
A17: TRANSV-1 | B17: QA y pruebas automatizadas transversales | C17: ~23.200 líneas de test en 3 proyectos (unitarias, integración, calibración) | D17: 90 | E17: =D17*(1+Resumen!$B$7) -> 63 | F17: =E17*Resumen!$B$6 -> 2835
A18: TRANSV-2 | B18: Documentación técnica, contratos de API y gestión | C18: Especificaciones base, ARQ, contratos, coordinación y reporte diario del sprint | D18: 124 | E18: =D18*(1+Resumen!$B$7) -> 86.8 | F18: =E18*Resumen!$B$6 -> 3906
B19: TOTAL MVP BASE | D19: =D16+D17+D18 -> 924 | E19: =E16+E17+E18 -> 646.8 | F19: =F16+F17+F18 -> 29106
B21: Contraste con lo facturado
B22: Precio cerrado cobrado por el sprint MVP (Propuesta Económica §5.1) | F22: 9750
B23: Ratio precio cobrado / costo de una fábrica colombiana con IA | F23: =F22/F19 -> 0.33498248
B24: Horas reales del sprint (evidencia git: 11 días activos, cadencia intensiva) | F24: 100

Sheet Resto ejecutado
A1: Resto — trabajo ya ejecutado (post-MVP)
A2: 14 jul – 10 ago 2026 · 128 commits · +39.826 / -1.901 líneas en src+tests · 'LOC medida' = churn atribuido por ID en el mensaje de commit
A4: ID nativo | B4: REQ | C4: Iniciativa | D4: Estado (hoja Estado) | E4: LOC medida | F4: Horas sin IA | G4: Horas con IA | H4: Valor (USD) | I4: Base de la estimación
A5: A. Desarrollado — registrado en la hoja Estado
A6: I-19 | B6: REQ-037 | C6: Consolidación progresiva de ideas | D6: Desarrollado | E6: 5012 | F6: 130 | G6: =F6*(1+Resumen!$B$7) -> 91 | H6: =G6*Resumen!$B$6 -> 4095 | I6: XXL. Idea canónica con versionado, reapertura, encolado, Markdown y API por idea, observabilidad de costo. 18 commits.
A7: I-18 | B7: REQ-036 | C7: Coaching secuencial por idea | D7: Desarrollado | E7: 1815 | F7: 56 | G7: =F7*(1+Resumen!$B$7) -> 39.2 | H7: =G7*Resumen!$B$6 -> 1764 | I7: L. Cola de ideas, contador y revisiones enlazadas.
A8: P-15 | B8: REQ-027 | C8: Refactor del orquestador conversacional | D8: Desarrollado | E8: 1888 | F8: 56 | G8: =F8*(1+Resumen!$B$7) -> 39.2 | H8: =G8*Resumen!$B$6 -> 1764 | I8: L. Remediación CAL-001: 3 cortes, extracción de política, transición y efectos.
A9: I-20 | B9: REQ-038 | C9: Redacción fluida + Markdown ejecutivo | D9: Desarrollado | E9: 1298 | F9: 56 | G9: =F9*(1+Resumen!$B$7) -> 39.2 | H9: =G9*Resumen!$B$6 -> 1764 | I9: L. Redactor LLM por acto con guardas deterministas; 4 cortes.
A10: I-17 | B10: REQ-025 | C10: BD de dos niveles de madurez + cierre por inactividad | D10: Desarrollado | E10: 1060 | F10: 40 | G10: =F10*(1+Resumen!$B$7) -> 28 | H10: =G10*Resumen!$B$6 -> 1260 | I10: M-L. Backend + portal; umbral configurable.
A11: I-06 | B11: REQ-019 | C11: Multi-idea (N registros por participante) | D11: Desarrollado | E11: 253 | F11: 40 | G11: =F11*(1+Resumen!$B$7) -> 28 | H11: =G11*Resumen!$B$6 -> 1260 | I11: M. Segmentación de múltiples ideas por mensaje; churn parcialmente fuera de la ventana medida.
A12: P-16 | B12: REQ-029 | C12: Refactor de página de campañas | D12: Desarrollado | E12: 1063 | F12: 32 | G12: =F12*(1+Resumen!$B$7) -> 22.4 | H12: =G12*Resumen!$B$6 -> 1008 | I12: M. Remediación CAL-002; 1.063 add / 963 del = reescritura.
A13: P-25 | B13: REQ-040 | C13: Coaching directo sin confirmación repetitiva | D13: Desarrollado | E13: n.d. | F13: 32 | G13: =F13*(1+Resumen!$B$7) -> 22.4 | H13: =G13*Resumen!$B$6 -> 1008 | I13: M. Cambio de flujo transversal; 583/583 tests.
A14: I-03 | B14: REQ-023 | C14: Follow-ups al eje débil de la rúbrica | D14: Desarrollado | E14: 464 | F14: 24 | G14: =F14*(1+Resumen!$B$7) -> 16.8 | H14: =G14*Resumen!$B$6 -> 756 | I14: S-M. Foco al eje débil sin revelar la rúbrica + filtro anti-fuga.
A15: P-03 | B15: REQ-015 | C15: Reinicio de datos por participante/campaña | D15: Desarrollado | E15: n.d. | F15: 24 | G15: =F15*(1+Resumen!$B$7) -> 16.8 | H15: =G15*Resumen!$B$6 -> 756 | I15: M. Herramienta interna de purga conservando configuración.
A16: P-21 | B16: REQ-033 | C16: Multi-número de WhatsApp | D16: Desarrollado | E16: 250 | F16: 24 | G16: =F16*(1+Resumen!$B$7) -> 16.8 | H16: =G16*Resumen!$B$6 -> 756 | I16: S-M. Enrutamiento por número entrante; 473/473 tests.
A17: I-05 | B17: REQ-021 | C17: Paráfrasis y transparencia | D17: Desarrollado | E17: 202 | F17: 16 | G17: =F17*(1+Resumen!$B$7) -> 11.2 | H17: =G17*Resumen!$B$6 -> 504 | I17: S. Paráfrasis por campaña con kill-switch.
A18: P-13 | B18: REQ-024 | C18: Umbral de cierre por campaña | D18: Desarrollado | E18: 210 | F18: 16 | G18: =F18*(1+Resumen!$B$7) -> 11.2 | H18: =G18*Resumen!$B$6 -> 504 | I18: S. Override por campaña + kill-switch.
A19: P-14 | B19: REQ-026 | C19: Vista de solo lectura de rúbricas y prompts | D19: Desarrollado | E19: 283 | F19: 16 | G19: =F19*(1+Resumen!$B$7) -> 11.2 | H19: =G19*Resumen!$B$6 -> 504 | I19: S. Frontend-only.
A20: I-16 | B20: REQ-018 | C20: Fix de calificación en Markdown | D20: Desarrollado | E20: n.d. | F20: 8 | G20: =F20*(1+Resumen!$B$7) -> 5.6 | H20: =G20*Resumen!$B$6 -> 252 | I20: XS. Bug: usar la evaluación más reciente.
C21: Subtotal | F21: =SUM(F6:F20) -> 570 | G21: =SUM(G6:G20) -> 399 | H21: =SUM(H6:H20) -> 17955
A23: B. En curso / en pruebas — registrado en la hoja Estado
A24: P-26 | B24: REQ-041 | C24: Campañas continuas y selección de campaña/pregunta | D24: En pruebas | E24: 4568 | F24: 110 | G24: =F24*(1+Resumen!$B$7) -> 77 | H24: =G24*Resumen!$B$6 -> 3465 | I24: XXL. 6 cortes: dominio, resolución multi-campaña, selección de pregunta, cupos móviles 24h, portal, observabilidad.
A25: I-08 | B25: REQ-022 | C25: Carga masiva de participantes (v1 + v2) | D25: En curso | E25: 4900 | F25: 90 | G25: =F25*(1+Resumen!$B$7) -> 63 | H25: =G25*Resumen!$B$6 -> 2835 | I25: XL. Backend + portal + plantilla oficial + conflictos + ficha de usuario. 2 versiones.
A26: P-27 | B26: REQ-042 | C26: Clasificación de intenciones de control | D26: En curso | E26: 1493 | F26: 56 | G26: =F26*(1+Resumen!$B$7) -> 39.2 | H26: =G26*Resumen!$B$6 -> 1764 | I26: L. Alias deterministas + clasificador LLM opt-in; 5 cortes.
A27: P-30 | B27: REQ-014 | C27: Reanudación de ideas anteriores | D27: En curso | E27: n.d. | F27: 48 | G27: =F27*(1+Resumen!$B$7) -> 33.6 | H27: =G27*Resumen!$B$6 -> 1512 | I27: L. 3 cortes; iniciada 05-ago.
A28: P-29 | B28: REQ-013 | C28: Cierre conversacional por tiempo | D28: En curso | E28: 899 | F28: 40 | G28: =F28*(1+Resumen!$B$7) -> 28 | H28: =G28*Resumen!$B$6 -> 1260 | I28: M. 2 cortes; voz humana + telemetría del aviso de pausa.
A29: P-28 | B29: REQ-012 | C29: Reactivación / despertar proactivo del coach | D29: En curso | E29: 875 | F29: 32 | G29: =F29*(1+Resumen!$B$7) -> 22.4 | H29: =G29*Resumen!$B$6 -> 1008 | I29: M. Saludo/inicio breve sin crear idea.
C30: Subtotal | F30: =SUM(F24:F29) -> 376 | G30: =SUM(G24:G29) -> 263.2 | H30: =SUM(H24:H29) -> 11844
A32: C. Ejecutado pero AUSENTE de la hoja Estado — riesgo de fuga de facturación
A33: P-32 | B33: — | C33: Corte 2 (iniciativa en curso, 10-ago) | D33: No registrado | E33: 2708 | F33: 56 | G33: =F33*(1+Resumen!$B$7) -> 39.2 | H33: =G33*Resumen!$B$6 -> 1764 | I33: L-XL. 2.708 líneas insertadas el 10-ago; sin fila en la hoja.
A34: D5 | B34: REQ-016 | C34: Banco de calibración de la evaluación | D34: No registrado | E34: n.d. | F34: 40 | G34: =F34*(1+Resumen!$B$7) -> 28 | H34: =G34*Resumen!$B$6 -> 1260 | I34: M. Librería + golden set (24 casos) + runner; proyecto ElTejido.Calibracion.
A35: P-10 | B35: REQ-017 | C35: Guardrails: cupos, rate por número y costo LLM | D35: No registrado | E35: n.d. | F35: 40 | G35: =F35*(1+Resumen!$B$7) -> 28 | H35: =G35*Resumen!$B$6 -> 1260 | I35: M. Backend hecho; portal pendiente.
A36: P-31 | B36: — | C36: Resumen de consolidación por umbral | D36: No registrado | E36: 438 | F36: 32 | G36: =F36*(1+Resumen!$B$7) -> 22.4 | H36: =G36*Resumen!$B$6 -> 1008 | I36: M. Especificada 06-ago; E2E cerrado 07-ago. Choca de ID con REQ-052 en la hoja.
A37: P-09 | B37: REQ-050 | C37: Monitoreo día D (health-check + runbook) | D37: No registrado | E37: n.d. | F37: 24 | G37: =F37*(1+Resumen!$B$7) -> 16.8 | H37: =G37*Resumen!$B$6 -> 756 | I37: S-M. Panel diferido; se conservan health-check y runbook.
A38: P-24 | B38: REQ-039 | C38: Evaluación implícita al solicitar mejora | D38: No registrado | E38: n.d. | F38: 24 | G38: =F38*(1+Resumen!$B$7) -> 16.8 | H38: =G38*Resumen!$B$6 -> 756 | I38: S-M. Bug de flujo; 579/579 tests.
A39: P-23 | B39: REQ-035 | C39: UX de resultados (maestro-detalle) | D39: No registrado | E39: 500 | F39: 20 | G39: =F39*(1+Resumen!$B$7) -> 14 | H39: =G39*Resumen!$B$6 -> 630 | I39: S. Frontend-only; 24/24 tests.
A40: P-17 | B40: REQ-028 | C40: Errores de API uniformes | D40: No registrado | E40: 121 | F40: 16 | G40: =F40*(1+Resumen!$B$7) -> 11.2 | H40: =G40*Resumen!$B$6 -> 504 | I40: S. Remediación API-001.
A41: P-22 | B41: REQ-034 | C41: UX de campañas | D41: No registrado | E41: 365 | F41: 16 | G41: =F41*(1+Resumen!$B$7) -> 11.2 | H41: =G41*Resumen!$B$6 -> 504 | I41: S. Frontend-only; 21/21 tests.
A42: P-18 | B42: REQ-030 | C42: Controles con nombre accesible | D42: No registrado | E42: 164 | F42: 12 | G42: =F42*(1+Resumen!$B$7) -> 8.4 | H42: =G42*Resumen!$B$6 -> 378 | I42: XS-S. Accesibilidad UXA11Y-001.
A43: P-19 | B43: REQ-031 | C43: Estados dinámicos accesibles | D43: No registrado | E43: 176 | F43: 12 | G43: =F43*(1+Resumen!$B$7) -> 8.4 | H43: =G43*Resumen!$B$6 -> 378 | I43: XS-S. Accesibilidad UXA11Y-002.
...

Sheet Resto diferido
A1: Resto — backlog diferido (aún no ejecutado)
A2: Estimación prospectiva a tarifa de fábrica colombiana. Es la base de la conversación de renovación con GHT.
A4: ID nativo | B4: REQ | C4: Iniciativa | D4: Horas sin IA | E4: Horas con IA | F4: Valor (USD) | G4: Supuesto / bloqueo
A5: P-05 | B5: REQ-046 | C5: Capa de insights | D5: 100 | E5: =D5*(1+Resumen!$B$7) -> 70 | F5: =E5*Resumen!$B$6 -> 3150 | G5: Extracción de hallazgos y patrones sobre el corpus de ideas. Requiere definir preguntas de negocio; alto componente de LLM y validación.
A6: REQ-053 | B6: REQ-053 | C6: Multidioma (inglés en el chatbot) | D6: 90 | E6: =D6*(1+Resumen!$B$7) -> 63 | F6: =E6*Resumen!$B$6 -> 2835 | G6: Toca plantilla HSM aprobada, prompts, vocabularios deterministas de intención y contenido de campaña. Sin especificar — rango real 60-140 h.
A7: P-04 | B7: REQ-045 | C7: Dashboard de resultados | D7: 80 | E7: =D7*(1+Resumen!$B$7) -> 56 | F7: =E7*Resumen!$B$6 -> 2520 | G7: Tablero visual en el portal. Frontend + endpoints de agregación.
A8: I-09 | B8: REQ-020 | C8: Tejido colectivo | D8: 60 | E8: =D8*(1+Resumen!$B$7) -> 42 | F8: =E8*Resumen!$B$6 -> 1890 | G8: Core ya implementado con flag OFF; restan Capa 3 + UI + validación de anonimización.
A9: P-06 | B9: REQ-047 | C9: Destilación por lotes | D9: 60 | E9: =D9*(1+Resumen!$B$7) -> 42 | F9: =E9*Resumen!$B$6 -> 1890 | G9: Procesamiento batch de grandes volúmenes. Requiere control de costo LLM.
A10: P-11 | B10: REQ-051 | C10: Informe consolidado | D10: 48 | E10: =D10*(1+Resumen!$B$7) -> 33.6 | F10: =E10*Resumen!$B$6 -> 1512 | G10: Informe por campaña; depende de P-04/P-05 para no duplicar agregaciones.
A11: P-08 | B11: REQ-049 | C11: Recordatorios / nudges | D11: 40 | E11: =D11*(1+Resumen!$B$7) -> 28 | F11: =E11*Resumen!$B$6 -> 1260 | G11: Bloqueado: requiere plantilla HSM aprobada por Meta.
A12: REQ-052 | B12: REQ-052 | C12: Manuales de parametrización | D12: 32 | E12: =D12*(1+Resumen!$B$7) -> 22.4 | F12: =E12*Resumen!$B$6 -> 1008 | G12: Documentación de funcionamiento y configuración. El ID REQ-052 también se usó para P-31.
A13: I-12 | B13: REQ-043 | C13: Seed thoughts por campaña | D13: 24 | E13: =D13*(1+Resumen!$B$7) -> 16.8 | F13: =E13*Resumen!$B$6 -> 756 | G13: BLOQUEADO: insumo de seeds vencido; escalar a Felipe.
A14: I-10 | B14: REQ-044 | C14: Flag base previa vs. en blanco | D14: 16 | E14: =D14*(1+Resumen!$B$7) -> 11.2 | F14: =E14*Resumen!$B$6 -> 504 | G14: Diferida con I-09 a Capa 3; campo ya en el modelo, OFF.
A15: P-07 | B15: REQ-048 | C15: Consentimiento de datos | D15: 16 | E15: =D15*(1+Resumen!$B$7) -> 11.2 | F15: =E15*Resumen!$B$6 -> 504 | G15: Diferida por ser herramienta interna (IP de GHT). Revisar exposición legal antes de descartar.
C16: TOTAL BACKLOG DIFERIDO | D16: =SUM(D5:D15) -> 566 | E16: =SUM(E5:E15) -> 396.2 | F16: =SUM(F5:F15) -> 17829
C18: Precio sugerido a pre-acordar con GHT (paquete cerrado, 15% de descuento por compromiso anticipado): | F18: =F16*0.85 -> 15154.65

Sheet Base de cálculo
A1: Base de cálculo, evidencia, fuentes y supuestos
A3: 1. Evidencia medida en el repositorio (git, corte 2026-08-10)
A4: Commits totales | B4: 209 | C4: git log
A5: Días con actividad de commit | B5: 34 | C5: 11 en jun, 15 en jul, 8 en ago
A6: Líneas de código en src/ (6 proyectos) | B6: 56.088 | C6: Api 4.262 · Application 17.579 · Domain 4.199 · Infrastructure 9.891 · Web 19.385 · Calibracion 772
A7: Líneas de código en tests/ (3 proyectos) | B7: 23.223 | C7: UnitTests 16.334 · IntegrationTests 6.610 · Calibracion 279
A8: Archivos fuente versionados | B8: 431 .cs + 37 .ts + 6 html/scss
A9: MVP (12–24 jun): churn en src+tests | B9: +30.057 / -46 en 319 archivos | C9: git diff root..último commit de junio
A10: Post-MVP (24 jun–10 ago): churn en src+tests | B10: +39.826 / -1.901 en 300 archivos | C10: git diff último-junio..HEAD
A12: 2. Tarifa de fábrica de software colombiana — fuentes (agosto 2026)
A13: Salario/tarifa directa del desarrollador senior en Colombia | B13: USD 32–40/h | C13: lemon.io Rate Calculator Colombia 2026. Seniors fuertes 42–45/h; mid 23–31/h.
A14: Perfiles Python / MLOps / LLM | B14: +37% sobre la mediana senior (~USD 46/h) | C14: lemon.io / Curotec — es el segmento de más rápido movimiento en 2026.
A15: Bill rate de agencia al cliente | B15: USD 25–60/h | C15: Kore BPO: dev mid a USD 26/h directo + ~40% de carga patronal = ~36/h, + 35% de margen ≈ 49/h de bill rate.
A16: Staffing nearshore (rango amplio) | B16: USD 45–110/h | C16: Kore BPO Nearshore Staffing Pricing 2026 — incluye perfiles US-facing con inglés C1.
A17: TARIFA USADA EN ESTE MODELO | B17: USD 45/h | C17: Blended de un equipo de fábrica (arquitecto + 2 devs + QA + PM) para stack .NET 8 + Angular + integración LLM. Escenarios 35 / 45 / 55 en la hoja Resumen.
A19: 3. Ajuste por uso de IA en la fábrica comparable — fuentes
A20: Experimentos controlados: tareas acotadas de código | B20: 30–55% más rápido | C20: Aplica a funciones, tests y boilerplate; no a diseño, integración ni depuración.
A21: McKinsey — 4.500 devs en 150 empresas | B21: -46% de tiempo en tareas rutinarias de código | C21: Solo la porción rutinaria del trabajo, no la entrega completa.
A22: DX — 135.000 desarrolladores | B22: 3,6 h ahorradas por semana (~9%) | C22: Efecto real medido a nivel de organización.
A23: Paradoja de productividad | B23: Más output individual, poca mejora de velocidad de entrega | C23: La coordinación, revisión y QA no se comprimen con IA.
A24: AJUSTE USADO EN ESTE MODELO | B24: -30% de horas | C24: Punto medio conservador entre el 46% de tarea y el ~10% organizacional. Una fábrica con adopción madura de IA, pero con su estructura de equipo, handoffs y ceremonias intacta.
A26: 4. Por qué GTA rinde 4,4x y una fábrica con IA no
A27: La fábrica comprime la codificación pero conserva la estructura: PM, analista, 2-3 devs, QA, ceremonias, handoffs y revisiones cruzadas. Ahí es donde se va el tiempo que la IA no toca.
A28: GTA opera con un experto único y agentes de IA: no hay traspaso de contexto, ni reunión de refinamiento, ni tiempo de espera entre roles. La especificación, el código y las pruebas los produce el mismo ciclo.
A29: El repositorio lo evidencia: 33 iniciativas en 22 días activos, con cortes documentados y suites de 579-698 tests corriendo en verde. Ese ritmo no es alcanzable con un pipeline de fábrica.
A30: Consecuencia comercial: la ventaja de GTA NO es la tarifa (que es 2,7x la colombiana), es el rendimiento por hora. Toda la negociación debe ocurrir en precio por alcance entregado, nunca en USD/h.
A32: 5. Método de estimación de horas
A33: Paso 1 | B33: Sizing por iniciativa | C33: T-shirt sizing calibrado contra el churn real atribuido por ID en el mensaje de commit (113 commits parseados, ventana 20-jul a 10-ago).
A34: Paso 2 | B34: Bandas aplicadas | C34: XS <200 LOC = 8-12 h · S 200-500 = 16-24 h · M 500-1.200 = 32-40 h · L 1.200-2.500 = 48-56 h · XL 2.500-5.000 = 90-110 h · XXL >5.000 = 130 h
A35: Paso 3 | B35: Validación cruzada | C35: Productividad implícita ≈ 33 LOC/h sin IA, consistente entre MVP (924 h / 30.057 LOC) y post-MVP (1.360 h / 39.826 LOC).
A36: Paso 4 | B36: Transversales | C36: QA automatizada, documentación, contratos de API y gestión se estiman aparte porque atraviesan todas las iniciativas.
A38: 6. Supuestos que hay que validar
A39: Tarifa USD 45/h: si el comparador real que GHT tiene sobre la mesa es una fábrica pequeña (USD 35/h), lo entregado vale ~USD 56.000 y el margen de negociación se estrecha.
A40: Ajuste de IA -30%: si se asume que la fábrica comparable NO usa IA, lo entregado sube a ~USD 103.000. Si se asume adopción agresiva (-50%), baja a ~USD 51.000.
A41: Horas reales de GTA (360 h): inferidas de la cadencia de commits, NO de un timesheet. Es el supuesto más sensible del modelo y conviene sustentarlo antes de negociar.
A42: Las horas de fábrica miden COSTO DE REPOSICIÓN, no precio de venta. No deben presentarse a GHT como una factura.
A43: El backlog diferido asume el alcance especificado hoy; REQ-053 (multidioma) no tiene spec cerrada.
A45: 7. Hallazgos de control en Seguimiento_Requerimientos.xlsx
A46: La hoja 'Estado' tiene 41 filas pero omite REQ-010 (Seguridad y guardrails), que sí está en 'Alcance inicial' y en el estado del 04-ago.
A47: 12 iniciativas ya ejecutadas no tienen fila en 'Estado': D5, P-07, P-09, P-10, P-17, P-18, P-19, P-20, P-22, P-23, P-24, P-31/P-32.
...
