Workbook

Sheet Resumen
A1: Estimación independiente del costo de desarrollo — El Tejido (GHT)
A2: Corte 2026-08-10 · Elaborado sobre evidencia de repositorio (git), specs y hoja Estado de Seguimiento_Requerimientos.xlsx
A4: Parámetros
A5: Tarifa de mercado (USD/h) | B5: 120 | C5: Tarifa blended agencia LATAM/nearshore para stack .NET 8 + Angular + LLM
A6: Tarifa contractual (USD/h) | B6: 121.88 | C6: USD 19.500 / 160 h mes — Propuesta Económica El Tejido, §5.3
A7: Capacidad mensual contratada (h) | B7: 160 | C7: Propuesta Económica El Tejido, §5.3
A8: Factor de compresión por desarrollo asistido por IA | B8: 6.3 | C8: Horas de mercado ÷ horas reales observadas (ver hoja Base de cálculo)
A11: Lente 1 — Costo de reposición a precios de mercado (equipo convencional, sin IA)
A12: Responde: ¿cuánto costaría hoy reconstruir esto contratando una fábrica de software?
A13: Bloque | B13: Horas estimadas | C13: Valor (USD) | D13: % del total
A14: MVP base (REQ-001 … REQ-011) | B14: ='MVP base'!D19 -> 924 | C14: =B14*$B$5 -> 110880 | D14: =C14/$C$18 -> 0.32421053
A15: Resto — ejecutado (33 iniciativas + transversal) | B15: ='Resto ejecutado'!F52 -> 1360 | C15: =B15*$B$5 -> 163200 | D15: =C15/$C$18 -> 0.47719298
A16: Resto — backlog diferido (11 iniciativas) | B16: ='Resto diferido'!D16 -> 566 | C16: =B16*$B$5 -> 67920 | D16: =C16/$C$18 -> 0.19859649
A17: TOTAL ENTREGADO A LA FECHA | B17: =SUM(B14:B15) -> 2284 | C17: =SUM(C14:C15) -> 274080 | D17: =C17/C18 -> 0.80140351
A18: TOTAL ENTREGADO + BACKLOG | B18: =SUM(B14:B16) -> 2850 | C18: =SUM(C14:C16) -> 342000 | D18: 1
A21: Lente 2 — Valor facturable bajo el contrato vigente (horas reales × tarifa contractual)
A22: Responde: ¿cuánto se puede facturar legítimamente a GHT bajo el modelo de capacidad ya acordado?
A23: Periodo | B23: Horas reales estimadas | C23: Meses-capacidad equiv. | D23: Valor (USD) | E23: Estado de facturación
A24: MVP base — sprint 13 al 22 jun 2026 | B24: 100 | C24: =B24/$B$7 -> 0.625 | D24: =B24*$B$6 -> 12188 | E24: Facturado (precio cerrado USD 9.750)
A25: Post-MVP — 14 jul al 10 ago 2026 | B25: 260 | C25: =B25/$B$7 -> 1.625 | D25: =B25*$B$6 -> 31688.8 | E25: NO FACTURADO
A26: TOTAL | B26: =SUM(B24:B25) -> 360 | C26: =SUM(C24:C25) -> 2.25 | D26: =SUM(D24:D25) -> 43876.8
A27: Facturado a la fecha | D27: 9750
A28: BRECHA PENDIENTE DE FACTURAR | D28: =D26-D27 -> 34126.8
A31: Lente 3 — Lectura comercial
A32: 1. GHT ha recibido a la fecha activo de software por un costo de reposición de mercado de ~USD 274.000, y ha pagado USD 9.750 (3,6%).
A33: 2. El diferencial no es un regalo: es el efecto del desarrollo asistido por IA (factor ~6,3x) más el subsidio comercial del sprint MVP a precio cerrado.
A34: 3. Bajo el propio modelo contractual (capacidad 160 h/mes) hay ~USD 34.000 de trabajo entregado y no facturado desde el 14-jul.
A35: 4. Riesgo de anclaje: si GHT interioriza USD 9.750 como el precio de 'un sistema completo', toda la evolución posterior queda mal anclada.
A36: 5. Recomendación: facturar el post-MVP como 2 ciclos de capacidad (USD 39.000) y presentar el costo de reposición como evidencia de valor entregado, no como precio.
A37: 6. El backlog diferido (566 h / USD 68.000 de mercado ≈ USD 11.000 a tarifa contractual con factor IA) es la conversación de renovación.

Sheet Propuesta facturación
A1: ¿Cuánto facturar por el resto ejecutado?
A2: Excluye el backlog diferido. Cliente con proyecto puntual y baja disposición a pagar; se preserva la tarifa contractual y se ajusta el alcance cobrable.
A4: 1. Reparto del esfuerzo real post-MVP (260 h estimadas)
A5: Grupo | B5: Horas de mercado | C5: % del total | D5: Horas reales | E5: ¿Cobrable? | F5: Criterio
A6: A. Desarrollado y registrado en la hoja Estado (15 iniciativas) | B6: 570 | C6: =B6/$B$10 -> 0.41911765 | D6: =C6*$B$13 -> 108.97059 | E6: Sí | F6: Trabajo con REQ asignado y trazable en la hoja de seguimiento.
A7: B. En curso / en pruebas y registrado (6 iniciativas) | B7: 376 | C7: =B7/$B$10 -> 0.27647059 | D7: =C7*$B$13 -> 71.882353 | E7: Sí | F7: P-26, I-08, P-27, P-28, P-29, P-30. Código completo local aunque con flags OFF.
A8: C. Ejecutado pero AUSENTE de la hoja Estado (12 iniciativas) | B8: 304 | C8: =B8/$B$10 -> 0.22352941 | D8: =C8*$B$13 -> 58.117647 | E8: No | F8: Sin aprobación previa ni registro. Cobrarlo abre una discusión que no conviene; se absorbe como concesión visible.
A9: D. Transversal: QA E2E y documentación | B9: 110 | C9: =B9/$B$10 -> 0.080882353 | D9: =C9*$B$13 -> 21.029412 | E9: Sí | F9: Soporta la entrega de A y B; se factura prorrateado.
A10: TOTAL | B10: =SUM(B6:B9) -> 1360 | D10: =SUM(D6:D9) -> 260
A12: Parámetros
A13: Horas reales post-MVP (14 jul – 10 ago) | B13: 260 | C13: Inferidas de la cadencia de commits: 22 días activos, ~1,2 FTE
A14: Horas cobrables (grupos A + B + D) | B14: =D6+D7+D9 -> 201.88235
A15: Horas absorbidas como concesión (grupo C) | B15: =D8 -> 58.117647
A16: Tarifa contractual (USD/h) | B16: 121.88 | C16: Propuesta Económica §5.3 — NO se descuenta
A18: 2. Escenarios de facturación
A19: Escenario | B19: Base de cálculo | C19: Valor (USD) | D19: Múltiplo vs. MVP | E19: Prob. de cierre | F19: Uso en la negociación
A20: Apertura — contrato literal | B20: 260 h reales × tarifa contractual | C20: =B13*B16 -> 31688.8 | D20: =C20/9750 -> 3.2501333 | E20: Baja | F20: Es lo que el contrato permite cobrar. Se pone sobre la mesa para anclar, no para cerrar.
A21: RECOMENDADO — cierre | B21: 202 h cobrables × tarifa contractual, con 58 h absorbidas | C21: =B14*B16 -> 24605.421 | D21: =C21/9750 -> 2.5236329 | E21: Alta | F21: Precio cerrado. La concesión de 58 h (USD 7.070) es visible y no cuesta tarifa.
A22: Piso — walk-away | B22: 1,25 ciclos de capacidad (200 h) | C22: =200*B16 -> 24376 | D22: =C22/9750 -> 2.5001026 | E22: Muy alta | F22: No bajar de aquí: por debajo el precio/hora efectivo cae bajo el del MVP y quema el ancla para la extensión.
A23: Rendición (no recomendado) | B23: 1 ciclo de capacidad (160 h) | C23: =160*B16 -> 19500.8 | D23: =C23/9750 -> 2.0000821 | E23: Casi segura | F23: Solo si el riesgo de relación es real. Cede USD 5.000 sin contrapartida.
A25: 3. Triangulación del número recomendado (USD 24.500)
A26: Tres métodos independientes convergen en el mismo rango:
A27: Método 1 — Esfuerzo cobrable | B27: 202 h × USD 121,88 | C27: =B14*B16 -> 24605.421
A28: Método 2 — Duración relativa al MVP | B28: El post-MVP tomó 20 días hábiles vs. 8 del sprint MVP = 2,5x × USD 9.750 | C28: =2.5*9750 -> 24375
A29: Método 3 — Ciclos de capacidad | B29: 1,25 ciclos de los 160 h/mes contratados × USD 19.500 | C29: =1.25*19500 -> 24375
A31: 4. Cómo se ve para GHT
A32: Ya facturado — MVP base | B32: =9750 -> 9750
A33: Propuesto — resto ejecutado | B33: =C21 -> 24605.421
A34: TOTAL DEL PROYECTO | B34: =B32+B33 -> 34355.421
A35: Costo de reposición de mercado de lo entregado | B35: =Resumen!C17 -> 274080
A36: GHT paga, sobre el costo de reposición | B36: =B34/B35 -> 0.12534815
A38: 5. Reglas de la negociación
A39: No descontar la tarifa. Se descuentan horas, nunca los USD 121,88/h: la tarifa es el activo que hay que proteger para la extensión.
A40: Poner la concesión sobre la mesa primero. 'Ejecutamos 33 iniciativas; les facturamos 21. Las 12 que no quedaron registradas las absorbemos (USD 7.070).' Eso compra el derecho a pedir el resto completo.
A41: Justificar el múltiplo 2,5x con volumen, no con esfuerzo: 33 iniciativas vs. 11 requerimientos, 4 semanas vs. 8 días hábiles, +39.826 líneas vs. +30.057.
A42: Nunca mostrar los USD 274.000 como precio. Se muestra como respaldo de valor solo si GHT cuestiona que 24.500 sea caro.
A43: Facilitar la aprobación, no el precio: si hay resistencia, ofrecer 2 cuotas (50% a la firma / 50% a 30 días) antes que bajar el número.
A44: Cerrar el diferido con precio pre-acordado (566 h de mercado). Convierte este cierre en una opción de renovación en lugar de un final.
A45: Condición innegociable: llenar las columnas Estimación/Horas/Tarifa de la hoja de seguimiento y firmar las aprobaciones antes de ejecutar la siguiente fase. Sin eso se repite la fuga.

Sheet MVP base
A1: MVP base — estimación independiente (REQ-001 a REQ-011)
A2: Sprint 13–24 jun 2026 · 81 commits · 319 archivos · 30.057 líneas netas en src+tests · Horas = equipo convencional a precios de mercado
A4: ID | B4: Requerimiento | C4: Alcance técnico que sustenta la estimación | D4: Horas | E4: Valor (USD) | F4: Complejidad
A5: REQ-011 | B5: Plataforma base (.NET 8, Cosmos, API REST, CI/CD) | C5: Solución modular de 6 proyectos, modelo de datos Cosmos, contrato REST, pipelines GitHub Actions, Directory.Build.props, IaC Azure | D5: 90 | E5: =D5*Resumen!$B$5 -> 10800 | F5: Alta
A6: REQ-001 | B6: Autenticación de administrador por OTP de WhatsApp | C6: Login passwordless, emisión/validación de OTP, sesión JWT, rate limit anti-abuso | D6: 40 | E6: =D6*Resumen!$B$5 -> 4800 | F6: Media
A7: REQ-002 | B7: Identidad y matrícula de participantes | C7: Resolución de identidad por número, validación de matrícula y estado activo por campaña | D7: 30 | E7: =D7*Resumen!$B$5 -> 3600 | F7: Media
A8: REQ-003 | B8: Gestión de campañas, usuarios y preguntas | C8: CRUD completo con asociaciones N:M, tags, validaciones y API | D8: 70 | E8: =D8*Resumen!$B$5 -> 8400 | F8: Media-Alta
A9: REQ-004 | B9: Envío de mensajes iniciales por WhatsApp | C9: Integración WhatsApp Cloud API, plantillas HSM, reenvío a no respondientes, reintento de fallidos, idempotencia | D9: 50 | E9: =D9*Resumen!$B$5 -> 6000 | F9: Media-Alta
A10: REQ-005 | B10: Captura conversacional de ideas y consolidación | C10: Orquestador conversacional con máquina de estados, paráfrasis, confirmación y consolidación sin pérdida — núcleo del sistema | D10: 110 | E10: =D10*Resumen!$B$5 -> 13200 | F10: Muy alta
A11: REQ-006 | B11: Rúbricas, prompts versionados y configuración LLM | C11: Rúbrica Markdown parametrizable, versionado y aprobación de prompts, config de proveedor LLM, custodia segura de API key | D11: 55 | E11: =D11*Resumen!$B$5 -> 6600 | F11: Alta
A12: REQ-007 | B12: Evaluación de ideas con LLM y retroalimentación | C12: Motor de evaluación por rúbrica, retro breve, máx. una repregunta, snapshots reproducibles para auditoría | D12: 70 | E12: =D12*Resumen!$B$5 -> 8400 | F12: Alta
A13: REQ-008 | B13: Compilación de artefactos Markdown por idea | C13: Generador de Markdown canónico con trazabilidad, consultable y regenerable | D13: 40 | E13: =D13*Resumen!$B$5 -> 4800 | F13: Media
A14: REQ-009 | B14: Portal administrativo Angular con marca GHT | C14: SPA Angular con marca GHT: usuarios, campañas, configuración y resultados (~19.400 líneas en ElTejido.Web) | D14: 95 | E14: =D14*Resumen!$B$5 -> 11400 | F14: Alta
A15: REQ-010 | B15: Seguridad, guardrails, trazabilidad y observabilidad | C15: Rate limiting, anti prompt-injection, firma de webhook, no fuga de secretos, telemetría y logs de seguridad | D15: 60 | E15: =D15*Resumen!$B$5 -> 7200 | F15: Alta
B16: Subtotal funcional | D16: =SUM(D5:D15) -> 710 | E16: =D16*Resumen!$B$5 -> 85200
A17: TRANSV-1 | B17: QA y pruebas automatizadas transversales | C17: ~23.200 líneas de test en 3 proyectos (unitarias, integración, calibración) | D17: 90 | E17: =D17*Resumen!$B$5 -> 10800
A18: TRANSV-2 | B18: Documentación técnica, contratos de API y gestión | C18: Especificaciones base, ARQ, contratos, coordinación y reporte diario del sprint | D18: 124 | E18: =D18*Resumen!$B$5 -> 14880
B19: TOTAL MVP BASE | D19: =D16+SUM(D17:D18) -> 924 | E19: =D19*Resumen!$B$5 -> 110880
B21: Contraste con lo facturado
B22: Precio cerrado cobrado por el sprint MVP (Propuesta Económica §5.1) | E22: 9750
B23: Ratio precio cobrado / costo de reposición de mercado | E23: =E22/E19 -> 0.0879329
B24: Horas reales estimadas del sprint (evidencia git: 11 días activos, cadencia intensiva) | E24: 100
B25: Nota: la fila D19 mide qué costaría reconstruirlo con un equipo convencional; no es lo que se debe cobrar.

Sheet Resto ejecutado
A1: Resto — trabajo ya ejecutado (post-MVP)
A2: 14 jul – 10 ago 2026 · 128 commits · 39.826 líneas insertadas / 1.901 eliminadas en src+tests · 'LOC medida' = churn atribuido por ID en el mensaje de commit
A4: ID nativo | B4: REQ | C4: Iniciativa | D4: Estado (hoja Estado) | E4: LOC medida | F4: Horas | G4: Valor (USD) | H4: Base de la estimación
A5: A. Desarrollado — registrado en la hoja Estado
A6: I-19 | B6: REQ-037 | C6: Consolidación progresiva de ideas | D6: Desarrollado | E6: 5012 | F6: 130 | G6: =F6*Resumen!$B$5 -> 15600 | H6: XXL. Idea canónica con versionado, reapertura, encolado, Markdown y API por idea, observabilidad de costo. 18 commits.
A7: I-18 | B7: REQ-036 | C7: Coaching secuencial por idea | D7: Desarrollado | E7: 1815 | F7: 56 | G7: =F7*Resumen!$B$5 -> 6720 | H7: L. Cola de ideas, contador y revisiones enlazadas.
A8: P-15 | B8: REQ-027 | C8: Refactor del orquestador conversacional | D8: Desarrollado | E8: 1888 | F8: 56 | G8: =F8*Resumen!$B$5 -> 6720 | H8: L. Remediación CAL-001: 3 cortes, extracción de política, transición y efectos.
A9: I-20 | B9: REQ-038 | C9: Redacción fluida + Markdown ejecutivo | D9: Desarrollado | E9: 1298 | F9: 56 | G9: =F9*Resumen!$B$5 -> 6720 | H9: L. Redactor LLM por acto con guardas deterministas; 4 cortes.
A10: I-17 | B10: REQ-025 | C10: BD de dos niveles de madurez + cierre por inactividad | D10: Desarrollado | E10: 1060 | F10: 40 | G10: =F10*Resumen!$B$5 -> 4800 | H10: M-L. Backend + portal; umbral configurable.
A11: I-06 | B11: REQ-019 | C11: Multi-idea (N registros por participante) | D11: Desarrollado | E11: 253 | F11: 40 | G11: =F11*Resumen!$B$5 -> 4800 | H11: M. Segmentación de múltiples ideas por mensaje; churn parcialmente fuera de la ventana medida.
A12: P-16 | B12: REQ-029 | C12: Refactor de página de campañas | D12: Desarrollado | E12: 1063 | F12: 32 | G12: =F12*Resumen!$B$5 -> 3840 | H12: M. Remediación CAL-002; 1.063 add / 963 del = reescritura.
A13: P-25 | B13: REQ-040 | C13: Coaching directo sin confirmación repetitiva | D13: Desarrollado | E13: n.d. | F13: 32 | G13: =F13*Resumen!$B$5 -> 3840 | H13: M. Cambio de flujo transversal; 583/583 tests.
A14: I-03 | B14: REQ-023 | C14: Follow-ups al eje débil de la rúbrica | D14: Desarrollado | E14: 464 | F14: 24 | G14: =F14*Resumen!$B$5 -> 2880 | H14: S-M. Foco al eje débil sin revelar la rúbrica + filtro anti-fuga.
A15: P-03 | B15: REQ-015 | C15: Reinicio de datos por participante/campaña | D15: Desarrollado | E15: n.d. | F15: 24 | G15: =F15*Resumen!$B$5 -> 2880 | H15: M. Herramienta interna de purga conservando configuración.
A16: P-21 | B16: REQ-033 | C16: Multi-número de WhatsApp | D16: Desarrollado | E16: 250 | F16: 24 | G16: =F16*Resumen!$B$5 -> 2880 | H16: S-M. Enrutamiento por número entrante; 473/473 tests.
A17: I-05 | B17: REQ-021 | C17: Paráfrasis y transparencia | D17: Desarrollado | E17: 202 | F17: 16 | G17: =F17*Resumen!$B$5 -> 1920 | H17: S. Paráfrasis por campaña con kill-switch.
A18: P-13 | B18: REQ-024 | C18: Umbral de cierre por campaña | D18: Desarrollado | E18: 210 | F18: 16 | G18: =F18*Resumen!$B$5 -> 1920 | H18: S. Override por campaña + kill-switch.
A19: P-14 | B19: REQ-026 | C19: Vista de solo lectura de rúbricas y prompts | D19: Desarrollado | E19: 283 | F19: 16 | G19: =F19*Resumen!$B$5 -> 1920 | H19: S. Frontend-only.
A20: I-16 | B20: REQ-018 | C20: Fix de calificación en Markdown | D20: Desarrollado | E20: n.d. | F20: 8 | G20: =F20*Resumen!$B$5 -> 960 | H20: XS. Bug: usar la evaluación más reciente.
C21: Subtotal | F21: =SUM(F6:F20) -> 570 | G21: =F21*Resumen!$B$5 -> 68400
A23: B. En curso / en pruebas — registrado en la hoja Estado
A24: P-26 | B24: REQ-041 | C24: Campañas continuas y selección de campaña/pregunta | D24: En pruebas | E24: 4568 | F24: 110 | G24: =F24*Resumen!$B$5 -> 13200 | H24: XXL. 6 cortes: dominio, resolución multi-campaña, selección de pregunta, cupos móviles 24h, portal, observabilidad.
A25: I-08 | B25: REQ-022 | C25: Carga masiva de participantes (v1 + v2) | D25: En curso | E25: 4900 | F25: 90 | G25: =F25*Resumen!$B$5 -> 10800 | H25: XL. Backend + portal + plantilla oficial + conflictos + ficha de usuario. 2 versiones.
A26: P-27 | B26: REQ-042 | C26: Clasificación de intenciones de control | D26: En curso | E26: 1493 | F26: 56 | G26: =F26*Resumen!$B$5 -> 6720 | H26: L. Alias deterministas + clasificador LLM opt-in; 5 cortes.
A27: P-30 | B27: REQ-014 | C27: Reanudación de ideas anteriores | D27: En curso | E27: n.d. | F27: 48 | G27: =F27*Resumen!$B$5 -> 5760 | H27: L. 3 cortes; iniciada 05-ago.
A28: P-29 | B28: REQ-013 | C28: Cierre conversacional por tiempo | D28: En curso | E28: 899 | F28: 40 | G28: =F28*Resumen!$B$5 -> 4800 | H28: M. 2 cortes; voz humana + telemetría del aviso de pausa.
A29: P-28 | B29: REQ-012 | C29: Reactivación / despertar proactivo del coach | D29: En curso | E29: 875 | F29: 32 | G29: =F29*Resumen!$B$5 -> 3840 | H29: M. Saludo/inicio breve sin crear idea.
C30: Subtotal | F30: =SUM(F24:F29) -> 376 | G30: =F30*Resumen!$B$5 -> 45120
A32: C. Ejecutado pero AUSENTE de la hoja Estado — riesgo de fuga de facturación
A33: P-32 | B33: — | C33: Corte 2 (iniciativa en curso, 10-ago) | D33: No registrado | E33: 2708 | F33: 56 | G33: =F33*Resumen!$B$5 -> 6720 | H33: L-XL. 2.708 líneas insertadas el 10-ago; sin fila en la hoja.
A34: D5 | B34: REQ-016 | C34: Banco de calibración de la evaluación | D34: No registrado | E34: n.d. | F34: 40 | G34: =F34*Resumen!$B$5 -> 4800 | H34: M. Librería + golden set (24 casos) + runner; proyecto ElTejido.Calibracion.
A35: P-10 | B35: REQ-017 | C35: Guardrails: cupos, rate por número y costo LLM | D35: No registrado | E35: n.d. | F35: 40 | G35: =F35*Resumen!$B$5 -> 4800 | H35: M. Backend hecho; portal pendiente.
A36: P-31 | B36: — | C36: Resumen de consolidación por umbral | D36: No registrado | E36: 438 | F36: 32 | G36: =F36*Resumen!$B$5 -> 3840 | H36: M. Especificada 06-ago; E2E cerrado 07-ago. Choca de ID con REQ-052 'Manuales' en la hoja.
A37: P-09 | B37: REQ-050 | C37: Monitoreo día D (health-check + runbook) | D37: No registrado | E37: n.d. | F37: 24 | G37: =F37*Resumen!$B$5 -> 2880 | H37: S-M. Panel diferido; se conservan health-check y runbook.
A38: P-24 | B38: REQ-039 | C38: Evaluación implícita al solicitar mejora | D38: No registrado | E38: n.d. | F38: 24 | G38: =F38*Resumen!$B$5 -> 2880 | H38: S-M. Bug de flujo; 579/579 tests.
A39: P-23 | B39: REQ-035 | C39: UX de resultados (maestro-detalle) | D39: No registrado | E39: 500 | F39: 20 | G39: =F39*Resumen!$B$5 -> 2400 | H39: S. Frontend-only; 24/24 tests.
A40: P-17 | B40: REQ-028 | C40: Errores de API uniformes | D40: No registrado | E40: 121 | F40: 16 | G40: =F40*Resumen!$B$5 -> 1920 | H40: S. Remediación API-001.
A41: P-22 | B41: REQ-034 | C41: UX de campañas | D41: No registrado | E41: 365 | F41: 16 | G41: =F41*Resumen!$B$5 -> 1920 | H41: S. Frontend-only; 21/21 tests.
A42: P-18 | B42: REQ-030 | C42: Controles con nombre accesible | D42: No registrado | E42: 164 | F42: 12 | G42: =F42*Resumen!$B$5 -> 1440 | H42: XS-S. Accesibilidad UXA11Y-001.
A43: P-19 | B43: REQ-031 | C43: Estados dinámicos accesibles | D43: No registrado | E43: 176 | F43: 12 | G43: =F43*Resumen!$B$5 -> 1440 | H43: XS-S. Accesibilidad UXA11Y-002.
...

Sheet Resto diferido
A1: Resto — backlog diferido (aún no ejecutado)
A2: Estimación prospectiva a precios de mercado. Es la base de la conversación de renovación con GHT.
A4: ID nativo | B4: REQ | C4: Iniciativa | D4: Horas | E4: Valor (USD) | F4: Supuesto / bloqueo
A5: P-05 | B5: REQ-046 | C5: Capa de insights | D5: 100 | E5: =D5*Resumen!$B$5 -> 12000 | F5: Extracción de hallazgos y patrones sobre el corpus de ideas. Requiere definir preguntas de negocio; alto componente de LLM y validación.
A6: REQ-053 | B6: REQ-053 | C6: Multidioma (inglés en el chatbot) | D6: 90 | E6: =D6*Resumen!$B$5 -> 10800 | F6: Toca plantilla HSM aprobada, prompts, vocabularios deterministas de intención y contenido de campaña. Aún sin especificar — estimación de rango alto.
A7: P-04 | B7: REQ-045 | C7: Dashboard de resultados | D7: 80 | E7: =D7*Resumen!$B$5 -> 9600 | F7: Tablero visual en el portal. Frontend + endpoints de agregación.
A8: I-09 | B8: REQ-020 | C8: Tejido colectivo | D8: 60 | E8: =D8*Resumen!$B$5 -> 7200 | F8: Core ya implementado con flag OFF; restan ~40 h de Capa 3 + UI + validación de anonimización.
A9: P-06 | B9: REQ-047 | C9: Destilación por lotes | D9: 60 | E9: =D9*Resumen!$B$5 -> 7200 | F9: Procesamiento batch de grandes volúmenes. Requiere control de costo LLM.
A10: P-11 | B10: REQ-051 | C10: Informe consolidado | D10: 48 | E10: =D10*Resumen!$B$5 -> 5760 | F10: Informe por campaña; depende de P-04/P-05 para no duplicar agregaciones.
A11: P-08 | B11: REQ-049 | C11: Recordatorios / nudges | D11: 40 | E11: =D11*Resumen!$B$5 -> 4800 | F11: Bloqueado: requiere plantilla HSM aprobada por Meta.
A12: REQ-052 | B12: REQ-052 | C12: Manuales de parametrización | D12: 32 | E12: =D12*Resumen!$B$5 -> 3840 | F12: Documentación de funcionamiento y configuración. Ojo: el ID REQ-052 también se usó para P-31 en el estado de agosto.
A13: I-12 | B13: REQ-043 | C13: Seed thoughts por campaña | D13: 24 | E13: =D13*Resumen!$B$5 -> 2880 | F13: BLOQUEADO: insumo de seeds vencido; escalar a Felipe.
A14: I-10 | B14: REQ-044 | C14: Flag base previa vs. en blanco | D14: 16 | E14: =D14*Resumen!$B$5 -> 1920 | F14: Diferida con I-09 a Capa 3; campo ya en el modelo, OFF.
A15: P-07 | B15: REQ-048 | C15: Consentimiento de datos | D15: 16 | E15: =D15*Resumen!$B$5 -> 1920 | F15: Diferida por ser herramienta interna (IP de GHT). Revisar exposición legal antes de descartar.
C16: TOTAL BACKLOG DIFERIDO | D16: =SUM(D5:D15) -> 566 | E16: =D16*Resumen!$B$5 -> 67920
C18: Equivalente a tarifa contractual aplicando el factor de compresión por IA (6,3x): | E18: =D16/Resumen!$B$8*Resumen!$B$6 -> 10949.854

Sheet Base de cálculo
A1: Base de cálculo, evidencia y supuestos
A3: 1. Evidencia medida en el repositorio (git, corte 2026-08-10)
A4: Commits totales | B4: 209 | C4: Fuente: git log
A5: Días con actividad de commit | B5: 34 | C5: 11 en jun, 15 en jul, 8 en ago
A6: Líneas de código en src/ (6 proyectos) | B6: 56.088 | C6: Api 4.262 · Application 17.579 · Domain 4.199 · Infrastructure 9.891 · Web 19.385 · Calibracion 772
A7: Líneas de código en tests/ (3 proyectos) | B7: 23.223 | C7: UnitTests 16.334 · IntegrationTests 6.610 · Calibracion 279
A8: Archivos fuente versionados | B8: 431 .cs + 37 .ts + 6 html/scss
A9: MVP (12–24 jun): churn en src+tests | B9: +30.057 / -46 en 319 archivos | C9: git diff root..último commit de junio
A10: Post-MVP (24 jun–10 ago): churn en src+tests | B10: +39.826 / -1.901 en 300 archivos | C10: git diff último-junio..HEAD
A12: 2. Método de estimación
A13: Paso 1 | B13: Sizing por iniciativa | C13: T-shirt sizing calibrado contra el churn real atribuido por ID en el mensaje de commit (ventana 20-jul a 10-ago, 113 commits parseados).
A14: Paso 2 | B14: Bandas aplicadas | C14: XS <200 LOC = 8-12 h · S 200-500 = 16-24 h · M 500-1.200 = 32-40 h · L 1.200-2.500 = 48-56 h · XL 2.500-5.000 = 90-110 h · XXL >5.000 = 130 h
A15: Paso 3 | B15: Validación cruzada | C15: Productividad implícita ≈ 33 LOC entregadas por hora, consistente entre MVP (924 h / 30.057 LOC) y post-MVP (1.360 h / 39.826 LOC).
A16: Paso 4 | B16: Transversales | C16: QA automatizada, documentación, contratos de API y gestión se estiman aparte porque atraviesan todas las iniciativas.
A18: 3. Supuestos que hay que validar contigo
A19: Tarifa de mercado USD 120/h: blended nearshore para .NET 8 + Angular + integración LLM. Si el comparador es una fábrica local, baja a USD 60-80/h; si es consultoría tier-1, sube a USD 160-200/h.
A20: Horas reales: 100 h para el MVP y 260 h post-MVP, inferidas de la cadencia de commits (34 días activos, ~1,2 FTE). NO son horas registradas en un timesheet.
A21: Factor de compresión 6,3x: cociente entre horas de mercado y horas reales. Es el supuesto más sensible de todo el modelo.
A22: Las horas de mercado miden COSTO DE REPOSICIÓN, no precio de venta. No deben presentarse a GHT como una factura.
A23: El backlog diferido asume alcance tal como está especificado hoy; REQ-053 (multidioma) no tiene spec cerrada y su rango real puede ser 60-140 h.
A25: 4. Hallazgos de control detectados en Seguimiento_Requerimientos.xlsx
A26: La hoja 'Estado' tiene 41 filas pero omite REQ-010 (Seguridad y guardrails), que sí está en la hoja 'Alcance inicial' y en el estado del 04-ago. El MVP base queda subrepresentado en 1 requerimiento.
A27: 12 iniciativas ya ejecutadas no tienen fila en la hoja 'Estado': D5, P-07, P-09, P-10, P-17, P-18, P-19, P-20, P-22, P-23, P-24, P-31/P-32. Son ~304 h de mercado sin registro de seguimiento.
A28: Colisión de ID: REQ-052 se usa para 'Manuales de parametrización' en la hoja Estado y para P-31 en el documento de estado del 06-ago.
A29: Las columnas Estimación (h), Horas reales, Tarifa/h y Valor estimado están vacías en las tres hojas de seguimiento. Sin ellas el modelo T&M no es auditable ni cobrable.
A30: La hoja 'Resumen' reporta 40 iniciativas con 0 horas y USD 0 de valor. Hoy el instrumento de control comercial no soporta ninguna factura.
A31: La regla de oro del README ('nada se ejecuta sin estado Aprobado y evidencia') no se está cumpliendo: la carpeta Aprobaciones/ está vacía y hay 33 iniciativas ejecutadas.
