Workbook

Sheet Alcance inicial
A1: ID | B1: Nombre | C1: Descripción | D1: Tipo | E1: Prioridad | F1: Estado | G1: Solicitado por | H1: Fecha solicitud | I1: Estimación (h) | J1: Horas reales | K1: Tarifa/h ($) | L1: Valor estimado ($) | M1: Valor a facturar ($) | N1: Aprobado por | O1: Fecha aprobación | P1: N.º factura | Q1: Notas
A2: REQ-001 | B2: Autenticación de administrador por OTP de WhatsApp | C2: Login del portal admin por código OTP enviado por WhatsApp. | D2: Nuevo | E2: Alta | F2: Entregado | G2: GHT (alcance base MVP) | H2: 2026-06-12 | L2: =IF(AND(I2<>"",K2<>""),I2*K2,"") | M2: =IF(AND(J2<>"",K2<>""),J2*K2,"") | N2: GHT | O2: 2026-06-12 | Q2: Alcance base MVP (no facturable T&M) · Ref: Base 06,04
A3: REQ-002 | B3: Identidad y matrícula de participantes | C3: Reconocer al participante por su número y validar matrícula/actividad. | D3: Nuevo | E3: Alta | F3: Entregado | G3: GHT (alcance base MVP) | H3: 2026-06-12 | L3: =IF(AND(I3<>"",K3<>""),I3*K3,"") | M3: =IF(AND(J3<>"",K3<>""),J3*K3,"") | N3: GHT | O3: 2026-06-12 | Q3: Alcance base MVP (no facturable T&M) · Ref: Base 06
A4: REQ-003 | B4: Gestión de campañas, usuarios y preguntas | C4: CRUD de usuarios, campañas, preguntas y tags con asociación de participantes. | D4: Nuevo | E4: Alta | F4: Cerrado | G4: GHT (alcance base MVP) | H4: 2026-06-12 | L4: =IF(AND(I4<>"",K4<>""),I4*K4,"") | M4: =IF(AND(J4<>"",K4<>""),J4*K4,"") | N4: GHT | O4: 2026-06-12 | P4: Facturado | Q4: Alcance base MVP (facturado como MVP base) · Ref: Base 07,11,04
A5: REQ-004 | B5: Envío de mensajes iniciales por WhatsApp | C5: Envío inicial con reenvío a no respondieron y reintento de fallidos. | D5: Nuevo | E5: Alta | F5: Cerrado | G5: GHT (alcance base MVP) | H5: 2026-06-12 | L5: =IF(AND(I5<>"",K5<>""),I5*K5,"") | M5: =IF(AND(J5<>"",K5<>""),J5*K5,"") | N5: GHT | O5: 2026-06-12 | P5: Facturado | Q5: Alcance base MVP (facturado como MVP base) · Ref: Base 05,07
A6: REQ-005 | B6: Captura conversacional y consolidación progresiva | C6: Orquestador WhatsApp: paráfrasis, confirmación, consolidación y enrutamiento. | D6: Nuevo | E6: Alta | F6: Cerrado | G6: GHT (alcance base MVP) | H6: 2026-06-12 | L6: =IF(AND(I6<>"",K6<>""),I6*K6,"") | M6: =IF(AND(J6<>"",K6<>""),J6*K6,"") | N6: GHT | O6: 2026-06-12 | P6: Facturado | Q6: Alcance base MVP (facturado como MVP base) · Ref: Base 05
A7: REQ-006 | B7: Rúbricas, prompts versionados y configuración LLM | C7: Rúbrica Markdown versionada, prompts aprobados y config LLM con API key segura. | D7: Nuevo | E7: Alta | F7: Cerrado | G7: GHT (alcance base MVP) | H7: 2026-06-12 | L7: =IF(AND(I7<>"",K7<>""),I7*K7,"") | M7: =IF(AND(J7<>"",K7<>""),J7*K7,"") | N7: GHT | O7: 2026-06-12 | P7: Facturado | Q7: Alcance base MVP (facturado como MVP base) · Ref: Base 07,10
A8: REQ-007 | B8: Evaluación de ideas con LLM y retroalimentación | C8: Evaluación de la versión confirmada con rúbrica; retro corta y repregunta única. | D8: Nuevo | E8: Alta | F8: Cerrado | G8: GHT (alcance base MVP) | H8: 2026-06-12 | L8: =IF(AND(I8<>"",K8<>""),I8*K8,"") | M8: =IF(AND(J8<>"",K8<>""),J8*K8,"") | N8: GHT | O8: 2026-06-12 | P8: Facturado | Q8: Alcance base MVP (facturado como MVP base) · Ref: Base 08,05
A9: REQ-008 | B9: Compilación de artefactos Markdown por idea | C9: Markdown canónico por idea, consultable y regenerable. | D9: Nuevo | E9: Media | F9: Cerrado | G9: GHT (alcance base MVP) | H9: 2026-06-12 | L9: =IF(AND(I9<>"",K9<>""),I9*K9,"") | M9: =IF(AND(J9<>"",K9<>""),J9*K9,"") | N9: GHT | O9: 2026-06-12 | P9: Facturado | Q9: Alcance base MVP (facturado como MVP base) · Ref: Base 09
A10: REQ-009 | B10: Portal administrativo Angular con marca GHT | C10: Portal admin Angular 22 que consume la API, con marca GHT. | D10: Nuevo | E10: Alta | F10: Cerrado | G10: GHT (alcance base MVP) | H10: 2026-06-12 | L10: =IF(AND(I10<>"",K10<>""),I10*K10,"") | M10: =IF(AND(J10<>"",K10<>""),J10*K10,"") | N10: GHT | O10: 2026-06-12 | P10: Facturado | Q10: Alcance base MVP (facturado como MVP base) · Ref: Base 11,04
A11: REQ-010 | B11: Seguridad, guardrails, trazabilidad y observabilidad | C11: Rate limiting, anti-injection, firma webhook, no fuga de secretos, telemetría. | D11: Nuevo | E11: Alta | F11: Cerrado | G11: GHT (alcance base MVP) | H11: 2026-06-12 | L11: =IF(AND(I11<>"",K11<>""),I11*K11,"") | M11: =IF(AND(J11<>"",K11<>""),J11*K11,"") | N11: GHT | O11: 2026-06-12 | P11: Facturado | Q11: Alcance base MVP (facturado como MVP base) · Ref: Base 10
A12: REQ-011 | B12: Plataforma base: arquitectura .NET 8, Cosmos, API REST y CI/CD | C12: Scaffolding modular, modelo Cosmos, contrato API y pipelines a Azure. | D12: Nuevo | E12: Alta | F12: Cerrado | G12: GHT (alcance base MVP) | H12: 2026-06-12 | L12: =IF(AND(I12<>"",K12<>""),I12*K12,"") | M12: =IF(AND(J12<>"",K12<>""),J12*K12,"") | N12: GHT | O12: 2026-06-12 | P12: Facturado | Q12: Alcance base MVP (facturado como MVP base) · Ref: Base 02,03,04,12
L15: =IF(AND(I15<>"",K15<>""),I15*K15,"") | M15: =IF(AND(J15<>"",K15<>""),J15*K15,"")
L16: =IF(AND(I16<>"",K16<>""),I16*K16,"") | M16: =IF(AND(J16<>"",K16<>""),J16*K16,"")
L17: =IF(AND(I17<>"",K17<>""),I17*K17,"") | M17: =IF(AND(J17<>"",K17<>""),J17*K17,"")
L18: =IF(AND(I18<>"",K18<>""),I18*K18,"") | M18: =IF(AND(J18<>"",K18<>""),J18*K18,"")
L19: =IF(AND(I19<>"",K19<>""),I19*K19,"") | M19: =IF(AND(J19<>"",K19<>""),J19*K19,"")
L20: =IF(AND(I20<>"",K20<>""),I20*K20,"") | M20: =IF(AND(J20<>"",K20<>""),J20*K20,"")
L21: =IF(AND(I21<>"",K21<>""),I21*K21,"") | M21: =IF(AND(J21<>"",K21<>""),J21*K21,"")
L22: =IF(AND(I22<>"",K22<>""),I22*K22,"") | M22: =IF(AND(J22<>"",K22<>""),J22*K22,"")
L23: =IF(AND(I23<>"",K23<>""),I23*K23,"") | M23: =IF(AND(J23<>"",K23<>""),J23*K23,"")
L24: =IF(AND(I24<>"",K24<>""),I24*K24,"") | M24: =IF(AND(J24<>"",K24<>""),J24*K24,"")
L25: =IF(AND(I25<>"",K25<>""),I25*K25,"") | M25: =IF(AND(J25<>"",K25<>""),J25*K25,"")
L26: =IF(AND(I26<>"",K26<>""),I26*K26,"") | M26: =IF(AND(J26<>"",K26<>""),J26*K26,"")
... L201: =IF(AND(I201<>"",K201<>""),I201*K201,"") | M201: =IF(AND(J201<>"",K201<>""),J201*K201,"")
A202: TOTALES | I202: =SUM(I2:I201) -> 0 | J202: =SUM(J2:J201) -> 0 | L202: =SUM(L2:L201) -> 0 | M202: =SUM(M2:M201) -> 0
A204: Leyenda:
A205: • Celdas azules = tú las llenas. Celdas negras (Valor estimado / Valor a facturar) = fórmulas automáticas.
A206: • Valor estimado = Estimación (h) × Tarifa/h. Valor a facturar = Horas reales × Tarifa/h.
A207: • Estado, Tipo y Prioridad tienen lista desplegable (ver hoja 'Listas').
A208: • Usa el mismo ID que el documento en Requerimientos/ (REQ-00X). Guarda evidencia en Aprobaciones/.

Sheet Nuevas iniciativas
A1: ID | B1: Título | C1: Descripción | D1: Tipo | E1: Prioridad | F1: Estado | G1: Solicitado por | H1: Fecha solicitud | I1: Estimación (h) | J1: Horas reales | K1: Tarifa/h ($) | L1: Valor estimado ($) | M1: Valor a facturar ($) | N1: Aprobado por | O1: Fecha aprobación | P1: N.º factura | Q1: Notas
A2: I-03 | B2: Follow-ups al eje débil | C2: Pista de foco al eje más débil de la rúbrica + filtro anti-fuga de rúbrica. | D2: Nuevo | E2: Alta | F2: Entregado | G2: GHT | L2: =IF(AND(I2<>"",K2<>""),I2*K2,"") | M2: =IF(AND(J2<>"",K2<>""),J2*K2,"") | Q2: DONE local 2026-07-21; D5 real pendiente · Ref: Especificaciones/Iniciativas/I-03_Followups_Eje_Debil.md
A3: I-05 | B3: Paráfrasis y transparencia | C3: Paráfrasis de la idea (por campaña, solo tras umbral) con kill-switch. | D3: Nuevo | E3: Alta | F3: Entregado | G3: GHT | L3: =IF(AND(I3<>"",K3<>""),I3*K3,"") | M3: =IF(AND(J3<>"",K3<>""),J3*K3,"") | Q3: DONE local 2026-07-20; D5 pendiente · Ref: Especificaciones/Iniciativas/I-05_Parafraseo_Transparencia.md
A4: I-06 | B4: Multi-idea (N registros) | C4: Varias ideas por participante como registros independientes (segmentación por campaña). | D4: Nuevo | E4: Alta | F4: Entregado | G4: GHT | L4: =IF(AND(I4<>"",K4<>""),I4*K4,"") | M4: =IF(AND(J4<>"",K4<>""),J4*K4,"") | Q4: Código DONE local 2026-07-15; flags OFF hasta D5/UAT/costo · Ref: Especificaciones/Iniciativas/I-06_Multi_Idea_N_Registros.md
A5: I-08 | B5: Carga masiva de participantes | C5: Importación masiva con Área/Empresa/Tags y variables demográficas. | D5: Nuevo | E5: Alta | F5: Entregado | G5: GHT | L5: =IF(AND(I5<>"",K5<>""),I5*K5,"") | M5: =IF(AND(J5<>"",K5<>""),J5*K5,"") | Q5: Backend+UI DONE; extensión demográfica pendiente (Munir) · Ref: Especificaciones/Iniciativas/I-08_Carga_Masiva_Participantes.md
A6: I-09 | B6: Tejido colectivo | C6: Conexión colectiva de ideas (base para ARMA/P-12). | D6: Nuevo | E6: Baja | F6: Propuesto | G6: GHT | L6: =IF(AND(I6<>"",K6<>""),I6*K6,"") | M6: =IF(AND(J6<>"",K6<>""),J6*K6,"") | Q6: Core DONE local, flag OFF; DIFERIDA Capa 3 · Ref: Especificaciones/Iniciativas/I-09_Tejido_Colectivo.md
A7: I-10 | B7: Flag base previa vs. en blanco | C7: UI de activación del tejido (base previa vs. en blanco). | D7: Nuevo | E7: Baja | F7: Propuesto | G7: GHT | L7: =IF(AND(I7<>"",K7<>""),I7*K7,"") | M7: =IF(AND(J7<>"",K7<>""),J7*K7,"") | Q7: DIFERIDA con I-09 (Capa 3); campo en modelo OFF · Ref: Especificaciones/Iniciativas/I-10_Flag_Base_Previa_vs_Blanco.md
A8: I-12 | B8: Seed thoughts | C8: Pensamientos semilla por campaña para orientar la captura. | D8: Nuevo | E8: Media | F8: Propuesto | G8: GHT | L8: =IF(AND(I8<>"",K8<>""),I8*K8,"") | M8: =IF(AND(J8<>"",K8<>""),J8*K8,"") | Q8: BLOCKED — insumo (seeds) vencido; escalar · Ref: Especificaciones/Iniciativas/I-12_Seed_Thoughts.md
A9: I-16 | B9: Fix de calificación en Markdown | C9: El Markdown usa la evaluación más reciente por fecha. | D9: Bug | E9: Alta | F9: Entregado | G9: GHT | L9: =IF(AND(I9<>"",K9<>""),I9*K9,"") | M9: =IF(AND(J9<>"",K9<>""),J9*K9,"") | Q9: DONE 2026-07-15 · Ref: Especificaciones/Iniciativas/I-16_Fix_Calificacion_Markdown.md
A10: I-17 | B10: BD de dos niveles de madurez | C10: Clasifica cada respuesta maduro/incubación por umbral; paráfrasis solo si madura. | D10: Nuevo | E10: Alta | F10: Entregado | G10: GHT | L10: =IF(AND(I10<>"",K10<>""),I10*K10,"") | M10: =IF(AND(J10<>"",K10<>""),J10*K10,"") | Q10: DONE local 2026-07-22 (6/6); D5 pendiente · Ref: Especificaciones/Iniciativas/I-17_BD_Dos_Niveles_Madurez.md
A11: I-18 | B11: Coaching secuencial por idea | C11: Afinar una idea a la vez con cola, contador y revisiones enlazadas. | D11: Nuevo | E11: Alta | F11: Entregado | G11: GHT | L11: =IF(AND(I11<>"",K11<>""),I11*K11,"") | M11: =IF(AND(J11<>"",K11<>""),J11*K11,"") | Q11: DONE local 2026-07-25; pendiente D5/UAT/costo · Ref: Especificaciones/Iniciativas/I-18_Coaching_Secuencial_Por_Idea.md
A12: I-19 | B12: Consolidación progresiva de ideas | C12: Idea canónica con versiones; se evalúa la versión completa confirmada; cola/reapertura. | D12: Nuevo | E12: Alta | F12: Entregado | G12: GHT | L12: =IF(AND(I12<>"",K12<>""),I12*K12,"") | M12: =IF(AND(J12<>"",K12<>""),J12*K12,"") | Q12: DONE local 2026-07-28; pendiente D5/UAT/costo · Ref: Especificaciones/Iniciativas/I-19_Consolidacion_Progresiva_Ideas.md
A13: I-20 | B13: Redacción fluida + Markdown ejecutivo | C13: Redactor LLM por acto controlado por servidor; Markdown con umbral/origen/escala. | D13: Nuevo | E13: Alta | F13: Entregado | G13: GHT | L13: =IF(AND(I13<>"",K13<>""),I13*K13,"") | M13: =IF(AND(J13<>"",K13<>""),J13*K13,"") | Q13: DONE local 2026-07-28; pendiente D5/UAT/costo · Ref: Especificaciones/Iniciativas/I-20_Redaccion_Conversacional_Fluida_y_Markdown_Ejecutivo.md
... A37: D5 | B37: Banco de calibración | C37: Librería + golden set (24) + runner para calibrar la evaluación. | D37: Nuevo | E37: Alta | F37: Entregado | G37: GHT | L37: =IF(AND(I37<>"",K37<>""),I37*K37,"") | M37: =IF(AND(J37<>"",K37<>""),J37*K37,"") | Q37: DONE 2026-07-14; baseline real pendiente · Ref: Especificaciones/Iniciativas/D5_Banco_Calibracion.md
A38: REQ-012 | B38: Despertar proactivo del coach | C38: El participante puede iniciar/reactivar la conversación aunque el sistema no le haya escrito o haya expirado por timeout. Prerrequisito de campañas continuas. | D38: Nuevo | E38: Alta | F38: Propuesto | G38: Felipe Arango (GHT) | H38: 2026-07-31 | L38: =IF(AND(I38<>"",K38<>""),I38*K38,"") | M38: =IF(AND(J38<>"",K38<>""),J38*K38,"") | Q38: Reunión 2026-07-31 (Felipe Arango). REQ: Nuevas iniciativas/REQ-012 · Spec: Especificaciones/Iniciativas/P-28_Despertar_Proactivo_Coach.md
A39: REQ-013 | B39: Cierre conversacional por tiempo | C39: Tras inactividad, el sistema pausa la charla con mensaje natural; combina disparo determinístico (tiempo) y redacción no determinística (LLM). Deja la idea reanudable. | D39: Cambio | E39: Alta | F39: Propuesto | G39: Felipe Arango (GHT) | H39: 2026-07-31 | L39: =IF(AND(I39<>"",K39<>""),I39*K39,"") | M39: =IF(AND(J39<>"",K39<>""),J39*K39,"") | Q39: Reunión 2026-07-31 (Felipe Arango). REQ: Nuevas iniciativas/REQ-013 · Spec: Especificaciones/Iniciativas/P-29_Cierre_Conversacional_Por_Tiempo.md
A40: REQ-014 | B40: Retomar ideas del pasado sin importar el estado | C40: El participante vuelve a una idea ya aportada/evaluada y sigue trabajándola; elige continuar una previa o crear una nueva. | D40: Nuevo | E40: Alta | F40: Propuesto | G40: Felipe Arango (GHT) | H40: 2026-07-31 | L40: =IF(AND(I40<>"",K40<>""),I40*K40,"") | M40: =IF(AND(J40<>"",K40<>""),J40*K40,"") | Q40: Reunión 2026-07-31 (Felipe Arango). REQ: Nuevas iniciativas/REQ-014 · Spec: Especificaciones/Iniciativas/P-30_Retomar_Ideas_Del_Pasado.md
A41: P-27 | B41: Clasificación flexible de intenciones de control | C41: Alias deterministas + clasificador LLM (opt-in) que propone aportar/finalizarIdea/finalizarParticipacion/ambigua; el servidor valida y ejecuta. | D41: Cambio | E41: Alta | F41: En curso | L41: =IF(AND(I41<>"",K41<>""),I41*K41,"") | M41: =IF(AND(J41<>"",K41<>""),J41*K41,"") | Q41: Cortes 1-4 DONE local 2026-08-02; corte 5 pendiente (cupos/telemetría/E2E/QAS) · Ref: Especificaciones/Iniciativas/P-27_Clasificacion_Flexible_Intenciones_Control.md
L42: =IF(AND(I42<>"",K42<>""),I42*K42,"") | M42: =IF(AND(J42<>"",K42<>""),J42*K42,"")
L43: =IF(AND(I43<>"",K43<>""),I43*K43,"") | M43: =IF(AND(J43<>"",K43<>""),J43*K43,"")
L44: =IF(AND(I44<>"",K44<>""),I44*K44,"") | M44: =IF(AND(J44<>"",K44<>""),J44*K44,"")
L45: =IF(AND(I45<>"",K45<>""),I45*K45,"") | M45: =IF(AND(J45<>"",K45<>""),J45*K45,"")
L46: =IF(AND(I46<>"",K46<>""),I46*K46,"") | M46: =IF(AND(J46<>"",K46<>""),J46*K46,"")
L47: =IF(AND(I47<>"",K47<>""),I47*K47,"") | M47: =IF(AND(J47<>"",K47<>""),J47*K47,"")
L48: =IF(AND(I48<>"",K48<>""),I48*K48,"") | M48: =IF(AND(J48<>"",K48<>""),J48*K48,"")
L49: =IF(AND(I49<>"",K49<>""),I49*K49,"") | M49: =IF(AND(J49<>"",K49<>""),J49*K49,"")
L50: =IF(AND(I50<>"",K50<>""),I50*K50,"") | M50: =IF(AND(J50<>"",K50<>""),J50*K50,"")
L51: =IF(AND(I51<>"",K51<>""),I51*K51,"") | M51: =IF(AND(J51<>"",K51<>""),J51*K51,"")
L52: =IF(AND(I52<>"",K52<>""),I52*K52,"") | M52: =IF(AND(J52<>"",K52<>""),J52*K52,"")
L53: =IF(AND(I53<>"",K53<>""),I53*K53,"") | M53: =IF(AND(J53<>"",K53<>""),J53*K53,"")
... L101: =IF(AND(I101<>"",K101<>""),I101*K101,"") | M101: =IF(AND(J101<>"",K101<>""),J101*K101,"")
A102: TOTALES | I102: =SUM(I2:I101) -> 0 | J102: =SUM(J2:J101) -> 0 | L102: =SUM(L2:L101) -> 0 | M102: =SUM(M2:M101) -> 0
A104: Leyenda:
A105: • Celdas azules = editables. Estimación/Horas/Tarifa se llenan al negociar cada iniciativa con el cliente.
A106: • Valor estimado = Estimación (h) × Tarifa/h. Valor a facturar = Horas reales × Tarifa/h.
A107: • Estado refleja el estado real de desarrollo (ver Notas). Para T&M, el cliente aprueba y se registran horas.
A108: • Cada fila referencia su spec en Especificaciones/Iniciativas/. Los IDs I-xx/P-xx son los nativos del proyecto.

Sheet Estado 20260804
A1: Estado de requerimientos — El Tejido (corte 2026-08-04)
A2: Atendido=entregado (código listo, activación pendiente en varios) · En curso=en pruebas/desarrollo · Pendiente=diferido/bloqueado. Código origen = spec (I/P/D).
A3: REQ | B3: Código origen | C3: Tipo | D3: Requerimiento | E3: enviar | F3: Grupo | G3: Estado | H3: Detalle ejecutivo (qué hace) | I3: Nota
A4: REQ-001 | B4: MVP base | C4: Nuevo | D4: Autenticación de administrador por OTP de WhatsApp | E4: 1 | F4: Atendido | G4: Atendido | H4: El administrador entra al portal sin contraseña: escribe su número y recibe un código por WhatsApp para acceder de forma segura. | I4: MVP base (cerrado y facturado)
A5: REQ-002 | B5: MVP base | C5: Nuevo | D5: Identidad y matrícula de participantes | E5: 1 | F5: Atendido | G5: Atendido | H5: El sistema reconoce a cada participante por su número de WhatsApp y solo deja participar a quienes están matriculados y activos en una campaña. | I5: MVP base
A6: REQ-003 | B6: MVP base | C6: Nuevo | D6: Gestión de campañas, usuarios y preguntas | E6: 1 | F6: Atendido | G6: Atendido | H6: Desde el portal se crean y editan campañas, usuarios y preguntas, y se asocian los participantes a cada campaña. | I6: MVP base
A7: REQ-004 | B7: MVP base | C7: Nuevo | D7: Envío de mensajes iniciales por WhatsApp | E7: 1 | F7: Atendido | G7: Atendido | H7: Permite enviar el mensaje inicial de la campaña a todos los participantes, reenviar a quienes no respondieron y reintentar los envíos fallidos. | I7: MVP base
A8: REQ-005 | B8: MVP base | C8: Nuevo | D8: Captura conversacional de ideas y consolidación | E8: 1 | F8: Atendido | G8: Atendido | H8: El coach por WhatsApp recibe la idea, la reformula para confirmar que la entendió y va armando la versión final sin perder lo aportado antes. | I8: MVP base
A9: REQ-006 | B9: MVP base | C9: Nuevo | D9: Rúbricas, prompts versionados y configuración LLM | E9: 1 | F9: Atendido | G9: Atendido | H9: El administrador carga la rúbrica de evaluación, ajusta y aprueba los textos guía y configura el modelo de IA, guardando la clave de forma segura. | I9: MVP base
A10: REQ-007 | B10: MVP base | C10: Nuevo | D10: Evaluación de ideas con LLM y retroalimentación | E10: 1 | F10: Atendido | G10: Atendido | H10: Cada idea confirmada se evalúa con IA según la rúbrica y devuelve una retroalimentación breve y útil, con una sola repregunta como máximo. | I10: MVP base
A11: REQ-008 | B11: MVP base | C11: Nuevo | D11: Compilación de artefactos Markdown por idea | E11: 1 | F11: Atendido | G11: Atendido | H11: Por cada idea se genera un documento ordenado con su evaluación, consultable desde el portal y que se puede regenerar cuando se necesite. | I11: MVP base
A12: REQ-009 | B12: MVP base | C12: Nuevo | D12: Portal administrativo Angular con marca GHT | E12: 1 | F12: Atendido | G12: Atendido | H12: Portal web de administración con la imagen de GHT para gestionar usuarios, campañas y configuración, y revisar los resultados de cada idea. | I12: MVP base
A13: REQ-010 | B13: MVP base | C13: Nuevo | D13: Seguridad, guardrails y observabilidad | E13: 0 | F13: Atendido | G13: Atendido | H13: Controles que protegen el sistema: límites de uso, verificación de los mensajes de WhatsApp, protección de datos y registro de actividad para auditoría. | I13: MVP base
A14: REQ-011 | B14: MVP base | C14: Nuevo | D14: Plataforma base (.NET 8, Cosmos, API, CI/CD) | E14: 1 | F14: Atendido | G14: Atendido | H14: La base técnica sobre la que corre todo: la aplicación, la base de datos, las conexiones y el despliegue automático. | I14: MVP base
A15: REQ-015 | B15: P-03 | C15: Soporte | D15: Reinicio de datos por participante/campaña | E15: 1 | F15: Atendido | G15: Atendido | H15: Herramienta interna para borrar y reiniciar conversaciones y respuestas de un participante o de una campaña completa, conservando configuración y usuarios (útil para pruebas). | I15: DONE local 13-14-jul
... A54: REQ-051 | B54: P-11 | C54: Nuevo | D54: Informe consolidado | E54: 1 | F54: Pendiente | G54: Diferido | H54: Genera un informe consolidado de resultados por campaña (deseable, futuro). | I54: Diferida (deseable)

Sheet Estado ejecutivo
A1: Estado de requerimientos — El Tejido (corte 2026-08-04)
A2: Atendido=entregado (código listo, activación pendiente en varios) · En curso=en pruebas/desarrollo · Pendiente=diferido/bloqueado. Código origen = spec (I/P/D).
A3: REQ | B3: Código origen | C3: Tipo | D3: Requerimiento | E3: enviar | F3: Grupo | G3: Estado | H3: Detalle ejecutivo (qué hace) | I3: Nota
A4: REQ-001 | B4: MVP base | C4: Nuevo | D4: Autenticación de administrador por OTP de WhatsApp | E4: 1 | F4: Atendido | G4: Atendido | H4: El administrador entra al portal sin contraseña: escribe su número y recibe un código por WhatsApp para acceder de forma segura. | I4: MVP base (cerrado y facturado)
A5: REQ-002 | B5: MVP base | C5: Nuevo | D5: Identidad y matrícula de participantes | E5: 1 | F5: Atendido | G5: Atendido | H5: El sistema reconoce a cada participante por su número de WhatsApp y solo deja participar a quienes están matriculados y activos en una campaña. | I5: MVP base
A6: REQ-003 | B6: MVP base | C6: Nuevo | D6: Gestión de campañas, usuarios y preguntas | E6: 1 | F6: Atendido | G6: Atendido | H6: Desde el portal se crean y editan campañas, usuarios y preguntas, y se asocian los participantes a cada campaña. | I6: MVP base
A7: REQ-004 | B7: MVP base | C7: Nuevo | D7: Envío de mensajes iniciales por WhatsApp | E7: 1 | F7: Atendido | G7: Atendido | H7: Permite enviar el mensaje inicial de la campaña a todos los participantes, reenviar a quienes no respondieron y reintentar los envíos fallidos. | I7: MVP base
A8: REQ-005 | B8: MVP base | C8: Nuevo | D8: Captura conversacional de ideas y consolidación | E8: 1 | F8: Atendido | G8: Atendido | H8: El coach por WhatsApp recibe la idea, la reformula para confirmar que la entendió y va armando la versión final sin perder lo aportado antes. | I8: MVP base
A9: REQ-006 | B9: MVP base | C9: Nuevo | D9: Rúbricas, prompts versionados y configuración LLM | E9: 1 | F9: Atendido | G9: Atendido | H9: El administrador carga la rúbrica de evaluación, ajusta y aprueba los textos guía y configura el modelo de IA, guardando la clave de forma segura. | I9: MVP base
A10: REQ-007 | B10: MVP base | C10: Nuevo | D10: Evaluación de ideas con LLM y retroalimentación | E10: 1 | F10: Atendido | G10: Atendido | H10: Cada idea confirmada se evalúa con IA según la rúbrica y devuelve una retroalimentación breve y útil, con una sola repregunta como máximo. | I10: MVP base
A11: REQ-008 | B11: MVP base | C11: Nuevo | D11: Compilación de artefactos Markdown por idea | E11: 1 | F11: Atendido | G11: Atendido | H11: Por cada idea se genera un documento ordenado con su evaluación, consultable desde el portal y que se puede regenerar cuando se necesite. | I11: MVP base
A12: REQ-009 | B12: MVP base | C12: Nuevo | D12: Portal administrativo Angular con marca GHT | E12: 1 | F12: Atendido | G12: Atendido | H12: Portal web de administración con la imagen de GHT para gestionar usuarios, campañas y configuración, y revisar los resultados de cada idea. | I12: MVP base
A13: REQ-010 | B13: MVP base | C13: Nuevo | D13: Seguridad, guardrails y observabilidad | E13: 0 | F13: Atendido | G13: Atendido | H13: Controles que protegen el sistema: límites de uso, verificación de los mensajes de WhatsApp, protección de datos y registro de actividad para auditoría. | I13: MVP base
A14: REQ-011 | B14: MVP base | C14: Nuevo | D14: Plataforma base (.NET 8, Cosmos, API, CI/CD) | E14: 1 | F14: Atendido | G14: Atendido | H14: La base técnica sobre la que corre todo: la aplicación, la base de datos, las conexiones y el despliegue automático. | I14: MVP base
A15: REQ-015 | B15: P-03 | C15: Soporte | D15: Reinicio de datos por participante/campaña | E15: 1 | F15: Atendido | G15: Atendido | H15: Herramienta interna para borrar y reiniciar conversaciones y respuestas de un participante o de una campaña completa, conservando configuración y usuarios (útil para pruebas). | I15: DONE local 13-14-jul
... A23: REQ-024 | B23: P-13 | C23: Cambio | D23: Umbral de cierre por campaña | E23: 1 | F23: Atendido | G23: Atendido | H23: Permite definir, por campaña, qué tan buena debe ser una idea para darla por cerrada automáticamente. | I23: DONE 21-jul; calibración pendiente
A24: REQ-025 | B24: I-17 | C24: Nuevo | D24: BD de dos niveles de madurez + cierre por inactividad | F24: Atendido | G24: Atendido | H24: Clasifica cada idea como 'madura' o 'en incubación' según un umbral, y cierra la conversación tras un tiempo de inactividad. | I24: DONE 22-jul (6/6)
A25: REQ-026 | B25: P-14 | C25: Nuevo | D25: Vista de solo lectura de rúbricas y prompts | F25: Atendido | G25: Atendido | H25: Pantalla en el portal para consultar (solo lectura) las rúbricas y los prompts configurados. | I25: DONE 22-jul; frontend-only
A26: REQ-027 | B26: P-15 | C26: Cambio | D26: Refactor del orquestador conversacional | F26: Atendido | G26: Atendido | H26: Mejora interna del motor de conversación para hacerlo más ordenado y mantenible, sin cambiar lo que ve el usuario. | I26: DONE 24-jul (CAL-001)
A27: REQ-028 | B27: P-17 | C27: Cambio | D27: Errores de API uniformes | F27: Atendido | G27: Atendido | H27: Unifica el formato de los mensajes de error del sistema para que sean consistentes y más fáciles de diagnosticar. | I27: DONE 24-jul (API-001)
A28: REQ-029 | B28: P-16 | C28: Cambio | D28: Refactor de página de campañas | F28: Atendido | G28: Atendido | H28: Reorganiza internamente la pantalla de campañas para hacerla más mantenible, conservando su funcionamiento. | I28: DONE 25-jul (CAL-002)
A29: REQ-030 | B29: P-18 | C29: Cambio | D29: Controles con nombre accesible | F29: Atendido | G29: Atendido | H29: Mejora de accesibilidad: los controles del portal tienen nombres que los lectores de pantalla pueden anunciar. | I29: DONE 25-jul
A30: REQ-031 | B30: P-19 | C30: Cambio | D30: Estados dinámicos accesibles | F30: Atendido | G30: Atendido | H30: Mejora de accesibilidad: los errores y confirmaciones se anuncian a las tecnologías de apoyo. | I30: DONE 25-jul
A31: REQ-032 | B31: P-20 | C31: Cambio | D31: Pestañas accesibles de campañas | F31: Atendido | G31: Atendido | H31: Mejora de accesibilidad: las pestañas de campañas se pueden navegar con teclado siguiendo estándares. | I31: DONE 25-jul
A32: REQ-033 | B32: P-21 | C32: Nuevo | D32: Multi-número de WhatsApp | F32: Atendido | G32: Atendido | H32: Soporta varios números de WhatsApp: el sistema responde por el mismo número por el que la persona escribió. | I32: DONE 25-jul; backend 473/473
A33: REQ-034 | B33: P-22 | C33: Cambio | D33: Mejoras de UX en campañas | F33: Atendido | G33: Atendido | H33: Mejoras de experiencia de uso en la pantalla de campañas: pasos más claros, ayudas y estados vacíos. | I33: DONE 25-jul; frontend-only
A34: REQ-035 | B34: P-23 | C34: Cambio | D34: Mejoras de UX en resultados | F34: Atendido | G34: Atendido | H34: Mejoras en la pantalla de resultados, con vista lista-detalle para revisar cada idea y su evaluación. | I34: DONE 25-jul; frontend-only
A35: REQ-036 | B35: I-18 | C35: Nuevo | D35: Coaching secuencial por idea | F35: Atendido | G35: Atendido | H35: Cuando una persona menciona varias ideas, el coach las trabaja de a una a la vez, de forma ordenada. | I35: DONE 25-jul; pendiente D5/UAT
... A54: REQ-051 | B54: P-11 | C54: Nuevo | D54: Informe consolidado | F54: Pendiente | G54: Diferido | H54: Genera un informe consolidado de resultados por campaña (deseable, futuro). | I54: Diferida (deseable)

Sheet Gantt
A1: Gantt — El Tejido: requerimientos e iniciativas (nomenclatura REQ unificada)
A2: Barras: verde=Atendido · azul=En curso/En pruebas · ámbar=Especificada/Pendiente/Diferido · rojo ◆=hito. Inicio ESTIMADO por sprint; Fin=fecha real de DONE. Edite Inicio/Fin y las barras se recalculan.
A3: Lo no implementado va sin fechas (sin barra): ponga Inicio/Fin y aparece la barra automáticamente.
A4: REQ | B4: Código origen | C4: Requerimiento / Iniciativa | D4: Estado | E4: Inicio | F4: Fin (real/est.) | G4: 46181 | H4: 46188 | I4: 46195 | J4: 46202 | K4: 46209 | L4: 46216 | M4: 46223 | N4: 46230 | O4: 46237 | P4: 46244 | Q4: 46251 | R4: 46258 | S4: 46265 | T4: 46272 | U4: 46279 | V4: 46286 | W4: 46293 | X4: Notas
A5: — | C5: HITO — Envío de inicio de campaña | D5: Hito | E5: 46244 | F5: 46244 | G5: =IF(AND($E5<>"",$F5<>"",G$4<=$F5,G$4+6>=$E5),"◆","") | H5: =IF(AND($E5<>"",$F5<>"",H$4<=$F5,H$4+6>=$E5),"◆","") | I5: =IF(AND($E5<>"",$F5<>"",I$4<=$F5,I$4+6>=$E5),"◆","") | J5: =IF(AND($E5<>"",$F5<>"",J$4<=$F5,J$4+6>=$E5),"◆","") | K5: =IF(AND($E5<>"",$F5<>"",K$4<=$F5,K$4+6>=$E5),"◆","") | L5: =IF(AND($E5<>"",$F5<>"",L$4<=$F5,L$4+6>=$E5),"◆","") | M5: =IF(AND($E5<>"",$F5<>"",M$4<=$F5,M$4+6>=$E5),"◆","") | N5: =IF(AND($E5<>"",$F5<>"",N$4<=$F5,N$4+6>=$E5),"◆","") | ... W5: =IF(AND($E5<>"",$F5<>"",W$4<=$F5,W$4+6>=$E5),"◆","") | X5: Fecha inamovible
A6: — | C6: Convención de gerentes | D6: Hito | E6: 46289 | F6: 46289 | G6: =IF(AND($E6<>"",$F6<>"",G$4<=$F6,G$4+6>=$E6),"◆","") | H6: =IF(AND($E6<>"",$F6<>"",H$4<=$F6,H$4+6>=$E6),"◆","") | I6: =IF(AND($E6<>"",$F6<>"",I$4<=$F6,I$4+6>=$E6),"◆","") | J6: =IF(AND($E6<>"",$F6<>"",J$4<=$F6,J$4+6>=$E6),"◆","") | K6: =IF(AND($E6<>"",$F6<>"",K$4<=$F6,K$4+6>=$E6),"◆","") | L6: =IF(AND($E6<>"",$F6<>"",L$4<=$F6,L$4+6>=$E6),"◆","") | M6: =IF(AND($E6<>"",$F6<>"",M$4<=$F6,M$4+6>=$E6),"◆","") | N6: =IF(AND($E6<>"",$F6<>"",N$4<=$F6,N$4+6>=$E6),"◆","") | ... W6: =IF(AND($E6<>"",$F6<>"",W$4<=$F6,W$4+6>=$E6),"◆","") | X6: ≈24-sep (confirmada)
A7: REQ-011 | B7: MVP base | C7: Plataforma base (.NET 8, Cosmos, API, CI/CD) | D7: Atendido | E7: 46186 | F7: 46193 | G7: =IF(AND($E7<>"",$F7<>"",G$4<=$F7,G$4+6>=$E7),"█","") -> █ | H7: =IF(AND($E7<>"",$F7<>"",H$4<=$F7,H$4+6>=$E7),"█","") -> █ | I7: =IF(AND($E7<>"",$F7<>"",I$4<=$F7,I$4+6>=$E7),"█","") | J7: =IF(AND($E7<>"",$F7<>"",J$4<=$F7,J$4+6>=$E7),"█","") | K7: =IF(AND($E7<>"",$F7<>"",K$4<=$F7,K$4+6>=$E7),"█","") | L7: =IF(AND($E7<>"",$F7<>"",L$4<=$F7,L$4+6>=$E7),"█","") | M7: =IF(AND($E7<>"",$F7<>"",M$4<=$F7,M$4+6>=$E7),"█","") | N7: =IF(AND($E7<>"",$F7<>"",N$4<=$F7,N$4+6>=$E7),"█","") | ... W7: =IF(AND($E7<>"",$F7<>"",W$4<=$F7,W$4+6>=$E7),"█","") | X7: MVP base
A8: REQ-001 | B8: MVP base | C8: Autenticación de administrador por OTP de WhatsApp | D8: Atendido | E8: 46188 | F8: 46195 | G8: =IF(AND($E8<>"",$F8<>"",G$4<=$F8,G$4+6>=$E8),"█","") | H8: =IF(AND($E8<>"",$F8<>"",H$4<=$F8,H$4+6>=$E8),"█","") -> █ | I8: =IF(AND($E8<>"",$F8<>"",I$4<=$F8,I$4+6>=$E8),"█","") -> █ | J8: =IF(AND($E8<>"",$F8<>"",J$4<=$F8,J$4+6>=$E8),"█","") | K8: =IF(AND($E8<>"",$F8<>"",K$4<=$F8,K$4+6>=$E8),"█","") | L8: =IF(AND($E8<>"",$F8<>"",L$4<=$F8,L$4+6>=$E8),"█","") | M8: =IF(AND($E8<>"",$F8<>"",M$4<=$F8,M$4+6>=$E8),"█","") | N8: =IF(AND($E8<>"",$F8<>"",N$4<=$F8,N$4+6>=$E8),"█","") | ... W8: =IF(AND($E8<>"",$F8<>"",W$4<=$F8,W$4+6>=$E8),"█","") | X8: MVP base (cerrado y facturado)
A9: REQ-002 | B9: MVP base | C9: Identidad y matrícula de participantes | D9: Atendido | E9: 46188 | F9: 46195 | G9: =IF(AND($E9<>"",$F9<>"",G$4<=$F9,G$4+6>=$E9),"█","") | H9: =IF(AND($E9<>"",$F9<>"",H$4<=$F9,H$4+6>=$E9),"█","") -> █ | I9: =IF(AND($E9<>"",$F9<>"",I$4<=$F9,I$4+6>=$E9),"█","") -> █ | J9: =IF(AND($E9<>"",$F9<>"",J$4<=$F9,J$4+6>=$E9),"█","") | K9: =IF(AND($E9<>"",$F9<>"",K$4<=$F9,K$4+6>=$E9),"█","") | L9: =IF(AND($E9<>"",$F9<>"",L$4<=$F9,L$4+6>=$E9),"█","") | M9: =IF(AND($E9<>"",$F9<>"",M$4<=$F9,M$4+6>=$E9),"█","") | N9: =IF(AND($E9<>"",$F9<>"",N$4<=$F9,N$4+6>=$E9),"█","") | ... W9: =IF(AND($E9<>"",$F9<>"",W$4<=$F9,W$4+6>=$E9),"█","") | X9: MVP base
A10: REQ-003 | B10: MVP base | C10: Gestión de campañas, usuarios y preguntas | D10: Atendido | E10: 46191 | F10: 46200 | G10: =IF(AND($E10<>"",$F10<>"",G$4<=$F10,G$4+6>=$E10),"█","") | H10: =IF(AND($E10<>"",$F10<>"",H$4<=$F10,H$4+6>=$E10),"█","") -> █ | I10: =IF(AND($E10<>"",$F10<>"",I$4<=$F10,I$4+6>=$E10),"█","") -> █ | J10: =IF(AND($E10<>"",$F10<>"",J$4<=$F10,J$4+6>=$E10),"█","") | K10: =IF(AND($E10<>"",$F10<>"",K$4<=$F10,K$4+6>=$E10),"█","") | L10: =IF(AND($E10<>"",$F10<>"",L$4<=$F10,L$4+6>=$E10),"█","") | M10: =IF(AND($E10<>"",$F10<>"",M$4<=$F10,M$4+6>=$E10),"█","") | N10: =IF(AND($E10<>"",$F10<>"",N$4<=$F10,N$4+6>=$E10),"█","") | ... W10: =IF(AND($E10<>"",$F10<>"",W$4<=$F10,W$4+6>=$E10),"█","") | X10: MVP base
A11: REQ-006 | B11: MVP base | C11: Rúbricas, prompts versionados y configuración LLM | D11: Atendido | E11: 46195 | F11: 46202 | G11: =IF(AND($E11<>"",$F11<>"",G$4<=$F11,G$4+6>=$E11),"█","") | H11: =IF(AND($E11<>"",$F11<>"",H$4<=$F11,H$4+6>=$E11),"█","") | I11: =IF(AND($E11<>"",$F11<>"",I$4<=$F11,I$4+6>=$E11),"█","") -> █ | J11: =IF(AND($E11<>"",$F11<>"",J$4<=$F11,J$4+6>=$E11),"█","") -> █ | K11: =IF(AND($E11<>"",$F11<>"",K$4<=$F11,K$4+6>=$E11),"█","") | L11: =IF(AND($E11<>"",$F11<>"",L$4<=$F11,L$4+6>=$E11),"█","") | M11: =IF(AND($E11<>"",$F11<>"",M$4<=$F11,M$4+6>=$E11),"█","") | N11: =IF(AND($E11<>"",$F11<>"",N$4<=$F11,N$4+6>=$E11),"█","") | ... W11: =IF(AND($E11<>"",$F11<>"",W$4<=$F11,W$4+6>=$E11),"█","") | X11: MVP base
A12: REQ-010 | B12: MVP base | C12: Seguridad, guardrails y observabilidad | D12: Atendido | E12: 46195 | F12: 46211 | G12: =IF(AND($E12<>"",$F12<>"",G$4<=$F12,G$4+6>=$E12),"█","") | H12: =IF(AND($E12<>"",$F12<>"",H$4<=$F12,H$4+6>=$E12),"█","") | I12: =IF(AND($E12<>"",$F12<>"",I$4<=$F12,I$4+6>=$E12),"█","") -> █ | J12: =IF(AND($E12<>"",$F12<>"",J$4<=$F12,J$4+6>=$E12),"█","") -> █ | K12: =IF(AND($E12<>"",$F12<>"",K$4<=$F12,K$4+6>=$E12),"█","") -> █ | L12: =IF(AND($E12<>"",$F12<>"",L$4<=$F12,L$4+6>=$E12),"█","") | M12: =IF(AND($E12<>"",$F12<>"",M$4<=$F12,M$4+6>=$E12),"█","") | N12: =IF(AND($E12<>"",$F12<>"",N$4<=$F12,N$4+6>=$E12),"█","") | ... W12: =IF(AND($E12<>"",$F12<>"",W$4<=$F12,W$4+6>=$E12),"█","") | X12: MVP base
A13: REQ-004 | B13: MVP base | C13: Envío de mensajes iniciales por WhatsApp | D13: Atendido | E13: 46197 | F13: 46204 | G13: =IF(AND($E13<>"",$F13<>"",G$4<=$F13,G$4+6>=$E13),"█","") | H13: =IF(AND($E13<>"",$F13<>"",H$4<=$F13,H$4+6>=$E13),"█","") | I13: =IF(AND($E13<>"",$F13<>"",I$4<=$F13,I$4+6>=$E13),"█","") -> █ | J13: =IF(AND($E13<>"",$F13<>"",J$4<=$F13,J$4+6>=$E13),"█","") -> █ | K13: =IF(AND($E13<>"",$F13<>"",K$4<=$F13,K$4+6>=$E13),"█","") | L13: =IF(AND($E13<>"",$F13<>"",L$4<=$F13,L$4+6>=$E13),"█","") | M13: =IF(AND($E13<>"",$F13<>"",M$4<=$F13,M$4+6>=$E13),"█","") | N13: =IF(AND($E13<>"",$F13<>"",N$4<=$F13,N$4+6>=$E13),"█","") | ... W13: =IF(AND($E13<>"",$F13<>"",W$4<=$F13,W$4+6>=$E13),"█","") | X13: MVP base
A14: REQ-009 | B14: MVP base | C14: Portal administrativo Angular con marca GHT | D14: Atendido | E14: 46198 | F14: 46209 | G14: =IF(AND($E14<>"",$F14<>"",G$4<=$F14,G$4+6>=$E14),"█","") | H14: =IF(AND($E14<>"",$F14<>"",H$4<=$F14,H$4+6>=$E14),"█","") | I14: =IF(AND($E14<>"",$F14<>"",I$4<=$F14,I$4+6>=$E14),"█","") -> █ | J14: =IF(AND($E14<>"",$F14<>"",J$4<=$F14,J$4+6>=$E14),"█","") -> █ | K14: =IF(AND($E14<>"",$F14<>"",K$4<=$F14,K$4+6>=$E14),"█","") -> █ | L14: =IF(AND($E14<>"",$F14<>"",L$4<=$F14,L$4+6>=$E14),"█","") | M14: =IF(AND($E14<>"",$F14<>"",M$4<=$F14,M$4+6>=$E14),"█","") | N14: =IF(AND($E14<>"",$F14<>"",N$4<=$F14,N$4+6>=$E14),"█","") | ... W14: =IF(AND($E14<>"",$F14<>"",W$4<=$F14,W$4+6>=$E14),"█","") | X14: MVP base
A15: REQ-005 | B15: MVP base | C15: Captura conversacional de ideas y consolidación | D15: Atendido | E15: 46200 | F15: 46207 | G15: =IF(AND($E15<>"",$F15<>"",G$4<=$F15,G$4+6>=$E15),"█","") | H15: =IF(AND($E15<>"",$F15<>"",H$4<=$F15,H$4+6>=$E15),"█","") | I15: =IF(AND($E15<>"",$F15<>"",I$4<=$F15,I$4+6>=$E15),"█","") -> █ | J15: =IF(AND($E15<>"",$F15<>"",J$4<=$F15,J$4+6>=$E15),"█","") -> █ | K15: =IF(AND($E15<>"",$F15<>"",K$4<=$F15,K$4+6>=$E15),"█","") | L15: =IF(AND($E15<>"",$F15<>"",L$4<=$F15,L$4+6>=$E15),"█","") | M15: =IF(AND($E15<>"",$F15<>"",M$4<=$F15,M$4+6>=$E15),"█","") | N15: =IF(AND($E15<>"",$F15<>"",N$4<=$F15,N$4+6>=$E15),"█","") | ... W15: =IF(AND($E15<>"",$F15<>"",W$4<=$F15,W$4+6>=$E15),"█","") | X15: MVP base
A16: REQ-007 | B16: MVP base | C16: Evaluación de ideas con LLM y retroalimentación | D16: Atendido | E16: 46202 | F16: 46207 | G16: =IF(AND($E16<>"",$F16<>"",G$4<=$F16,G$4+6>=$E16),"█","") | H16: =IF(AND($E16<>"",$F16<>"",H$4<=$F16,H$4+6>=$E16),"█","") | I16: =IF(AND($E16<>"",$F16<>"",I$4<=$F16,I$4+6>=$E16),"█","") | J16: =IF(AND($E16<>"",$F16<>"",J$4<=$F16,J$4+6>=$E16),"█","") -> █ | K16: =IF(AND($E16<>"",$F16<>"",K$4<=$F16,K$4+6>=$E16),"█","") | L16: =IF(AND($E16<>"",$F16<>"",L$4<=$F16,L$4+6>=$E16),"█","") | M16: =IF(AND($E16<>"",$F16<>"",M$4<=$F16,M$4+6>=$E16),"█","") | N16: =IF(AND($E16<>"",$F16<>"",N$4<=$F16,N$4+6>=$E16),"█","") | ... W16: =IF(AND($E16<>"",$F16<>"",W$4<=$F16,W$4+6>=$E16),"█","") | X16: MVP base
A17: REQ-008 | B17: MVP base | C17: Compilación de artefactos Markdown por idea | D17: Atendido | E17: 46204 | F17: 46209 | G17: =IF(AND($E17<>"",$F17<>"",G$4<=$F17,G$4+6>=$E17),"█","") | H17: =IF(AND($E17<>"",$F17<>"",H$4<=$F17,H$4+6>=$E17),"█","") | I17: =IF(AND($E17<>"",$F17<>"",I$4<=$F17,I$4+6>=$E17),"█","") | J17: =IF(AND($E17<>"",$F17<>"",J$4<=$F17,J$4+6>=$E17),"█","") -> █ | K17: =IF(AND($E17<>"",$F17<>"",K$4<=$F17,K$4+6>=$E17),"█","") -> █ | L17: =IF(AND($E17<>"",$F17<>"",L$4<=$F17,L$4+6>=$E17),"█","") | M17: =IF(AND($E17<>"",$F17<>"",M$4<=$F17,M$4+6>=$E17),"█","") | N17: =IF(AND($E17<>"",$F17<>"",N$4<=$F17,N$4+6>=$E17),"█","") | ... W17: =IF(AND($E17<>"",$F17<>"",W$4<=$F17,W$4+6>=$E17),"█","") | X17: MVP base
A18: REQ-015 | B18: P-03 | C18: Reinicio de datos por participante/campaña | D18: Atendido | E18: 46216 | F18: 46217 | G18: =IF(AND($E18<>"",$F18<>"",G$4<=$F18,G$4+6>=$E18),"█","") | H18: =IF(AND($E18<>"",$F18<>"",H$4<=$F18,H$4+6>=$E18),"█","") | I18: =IF(AND($E18<>"",$F18<>"",I$4<=$F18,I$4+6>=$E18),"█","") | J18: =IF(AND($E18<>"",$F18<>"",J$4<=$F18,J$4+6>=$E18),"█","") | K18: =IF(AND($E18<>"",$F18<>"",K$4<=$F18,K$4+6>=$E18),"█","") | L18: =IF(AND($E18<>"",$F18<>"",L$4<=$F18,L$4+6>=$E18),"█","") -> █ | M18: =IF(AND($E18<>"",$F18<>"",M$4<=$F18,M$4+6>=$E18),"█","") | N18: =IF(AND($E18<>"",$F18<>"",N$4<=$F18,N$4+6>=$E18),"█","") | ... W18: =IF(AND($E18<>"",$F18<>"",W$4<=$F18,W$4+6>=$E18),"█","") | X18: DONE local 13-14-jul
... A47: REQ-013 | B47: P-29 | C47: Cierre conversacional por tiempo | D47: En curso | E47: 46237 | F47: 46238 | G47: =IF(AND($E47<>"",$F47<>"",G$4<=$F47,G$4+6>=$E47),"█","") | H47: =IF(AND($E47<>"",$F47<>"",H$4<=$F47,H$4+6>=$E47),"█","") | I47: =IF(AND($E47<>"",$F47<>"",I$4<=$F47,I$4+6>=$E47),"█","") | J47: =IF(AND($E47<>"",$F47<>"",J$4<=$F47,J$4+6>=$E47),"█","") | K47: =IF(AND($E47<>"",$F47<>"",K$4<=$F47,K$4+6>=$E47),"█","") | L47: =IF(AND($E47<>"",$F47<>"",L$4<=$F47,L$4+6>=$E47),"█","") | M47: =IF(AND($E47<>"",$F47<>"",M$4<=$F47,M$4+6>=$E47),"█","") | N47: =IF(AND($E47<>"",$F47<>"",N$4<=$F47,N$4+6>=$E47),"█","") | ... W47: =IF(AND($E47<>"",$F47<>"",W$4<=$F47,W$4+6>=$E47),"█","") | X47: En desarrollo: corte 1 de 2 hecho 04-ago; pendiente redacción LLM + E2E
A48: REQ-014 | B48: P-30 | C48: Reanudación de ideas anteriores | D48: Especificada | G48: =IF(AND($E48<>"",$F48<>"",G$4<=$F48,G$4+6>=$E48),"█","") | H48: =IF(AND($E48<>"",$F48<>"",H$4<=$F48,H$4+6>=$E48),"█","") | I48: =IF(AND($E48<>"",$F48<>"",I$4<=$F48,I$4+6>=$E48),"█","") | J48: =IF(AND($E48<>"",$F48<>"",J$4<=$F48,J$4+6>=$E48),"█","") | K48: =IF(AND($E48<>"",$F48<>"",K$4<=$F48,K$4+6>=$E48),"█","") | L48: =IF(AND($E48<>"",$F48<>"",L$4<=$F48,L$4+6>=$E48),"█","") | M48: =IF(AND($E48<>"",$F48<>"",M$4<=$F48,M$4+6>=$E48),"█","") | N48: =IF(AND($E48<>"",$F48<>"",N$4<=$F48,N$4+6>=$E48),"█","") | ... W48: =IF(AND($E48<>"",$F48<>"",W$4<=$F48,W$4+6>=$E48),"█","") | X48: Especificada; próxima a iniciar (3 cortes); kill-switch OFF
A49: REQ-043 | B49: I-12 | C49: Seed thoughts por campaña | D49: Bloqueado | G49: =IF(AND($E49<>"",$F49<>"",G$4<=$F49,G$4+6>=$E49),"█","") | H49: =IF(AND($E49<>"",$F49<>"",H$4<=$F49,H$4+6>=$E49),"█","") | I49: =IF(AND($E49<>"",$F49<>"",I$4<=$F49,I$4+6>=$E49),"█","") | J49: =IF(AND($E49<>"",$F49<>"",J$4<=$F49,J$4+6>=$E49),"█","") | K49: =IF(AND($E49<>"",$F49<>"",K$4<=$F49,K$4+6>=$E49),"█","") | L49: =IF(AND($E49<>"",$F49<>"",L$4<=$F49,L$4+6>=$E49),"█","") | M49: =IF(AND($E49<>"",$F49<>"",M$4<=$F49,M$4+6>=$E49),"█","") | N49: =IF(AND($E49<>"",$F49<>"",N$4<=$F49,N$4+6>=$E49),"█","") | ... W49: =IF(AND($E49<>"",$F49<>"",W$4<=$F49,W$4+6>=$E49),"█","") | X49: Bloqueado: insumo de seeds vencido (escalar)
A50: REQ-044 | B50: I-10 | C50: Flag base previa vs. en blanco | D50: Diferido | G50: =IF(AND($E50<>"",$F50<>"",G$4<=$F50,G$4+6>=$E50),"█","") | H50: =IF(AND($E50<>"",$F50<>"",H$4<=$F50,H$4+6>=$E50),"█","") | I50: =IF(AND($E50<>"",$F50<>"",I$4<=$F50,I$4+6>=$E50),"█","") | J50: =IF(AND($E50<>"",$F50<>"",J$4<=$F50,J$4+6>=$E50),"█","") | K50: =IF(AND($E50<>"",$F50<>"",K$4<=$F50,K$4+6>=$E50),"█","") | L50: =IF(AND($E50<>"",$F50<>"",L$4<=$F50,L$4+6>=$E50),"█","") | M50: =IF(AND($E50<>"",$F50<>"",M$4<=$F50,M$4+6>=$E50),"█","") | N50: =IF(AND($E50<>"",$F50<>"",N$4<=$F50,N$4+6>=$E50),"█","") | ... W50: =IF(AND($E50<>"",$F50<>"",W$4<=$F50,W$4+6>=$E50),"█","") | X50: Diferida a Capa 3
A51: REQ-045 | B51: P-04 | C51: Dashboard de resultados | D51: Diferido | G51: =IF(AND($E51<>"",$F51<>"",G$4<=$F51,G$4+6>=$E51),"█","") | H51: =IF(AND($E51<>"",$F51<>"",H$4<=$F51,H$4+6>=$E51),"█","") | I51: =IF(AND($E51<>"",$F51<>"",I$4<=$F51,I$4+6>=$E51),"█","") | J51: =IF(AND($E51<>"",$F51<>"",J$4<=$F51,J$4+6>=$E51),"█","") | K51: =IF(AND($E51<>"",$F51<>"",K$4<=$F51,K$4+6>=$E51),"█","") | L51: =IF(AND($E51<>"",$F51<>"",L$4<=$F51,L$4+6>=$E51),"█","") | M51: =IF(AND($E51<>"",$F51<>"",M$4<=$F51,M$4+6>=$E51),"█","") | N51: =IF(AND($E51<>"",$F51<>"",N$4<=$F51,N$4+6>=$E51),"█","") | ... W51: =IF(AND($E51<>"",$F51<>"",W$4<=$F51,W$4+6>=$E51),"█","") | X51: Diferida (deseable)
A52: REQ-046 | B52: P-05 | C52: Capa de insights | D52: Diferido | G52: =IF(AND($E52<>"",$F52<>"",G$4<=$F52,G$4+6>=$E52),"█","") | H52: =IF(AND($E52<>"",$F52<>"",H$4<=$F52,H$4+6>=$E52),"█","") | I52: =IF(AND($E52<>"",$F52<>"",I$4<=$F52,I$4+6>=$E52),"█","") | J52: =IF(AND($E52<>"",$F52<>"",J$4<=$F52,J$4+6>=$E52),"█","") | K52: =IF(AND($E52<>"",$F52<>"",K$4<=$F52,K$4+6>=$E52),"█","") | L52: =IF(AND($E52<>"",$F52<>"",L$4<=$F52,L$4+6>=$E52),"█","") | M52: =IF(AND($E52<>"",$F52<>"",M$4<=$F52,M$4+6>=$E52),"█","") | N52: =IF(AND($E52<>"",$F52<>"",N$4<=$F52,N$4+6>=$E52),"█","") | ... W52: =IF(AND($E52<>"",$F52<>"",W$4<=$F52,W$4+6>=$E52),"█","") | X52: Diferida post-convención
A53: REQ-047 | B53: P-06 | C53: Destilación por lotes | D53: Diferido | G53: =IF(AND($E53<>"",$F53<>"",G$4<=$F53,G$4+6>=$E53),"█","") | H53: =IF(AND($E53<>"",$F53<>"",H$4<=$F53,H$4+6>=$E53),"█","") | I53: =IF(AND($E53<>"",$F53<>"",I$4<=$F53,I$4+6>=$E53),"█","") | J53: =IF(AND($E53<>"",$F53<>"",J$4<=$F53,J$4+6>=$E53),"█","") | K53: =IF(AND($E53<>"",$F53<>"",K$4<=$F53,K$4+6>=$E53),"█","") | L53: =IF(AND($E53<>"",$F53<>"",L$4<=$F53,L$4+6>=$E53),"█","") | M53: =IF(AND($E53<>"",$F53<>"",M$4<=$F53,M$4+6>=$E53),"█","") | N53: =IF(AND($E53<>"",$F53<>"",N$4<=$F53,N$4+6>=$E53),"█","") | ... W53: =IF(AND($E53<>"",$F53<>"",W$4<=$F53,W$4+6>=$E53),"█","") | X53: Diferida post-convención
A54: REQ-048 | B54: P-07 | C54: Consentimiento de datos | D54: Diferido | G54: =IF(AND($E54<>"",$F54<>"",G$4<=$F54,G$4+6>=$E54),"█","") | H54: =IF(AND($E54<>"",$F54<>"",H$4<=$F54,H$4+6>=$E54),"█","") | I54: =IF(AND($E54<>"",$F54<>"",I$4<=$F54,I$4+6>=$E54),"█","") | J54: =IF(AND($E54<>"",$F54<>"",J$4<=$F54,J$4+6>=$E54),"█","") | K54: =IF(AND($E54<>"",$F54<>"",K$4<=$F54,K$4+6>=$E54),"█","") | L54: =IF(AND($E54<>"",$F54<>"",L$4<=$F54,L$4+6>=$E54),"█","") | M54: =IF(AND($E54<>"",$F54<>"",M$4<=$F54,M$4+6>=$E54),"█","") | N54: =IF(AND($E54<>"",$F54<>"",N$4<=$F54,N$4+6>=$E54),"█","") | ... W54: =IF(AND($E54<>"",$F54<>"",W$4<=$F54,W$4+6>=$E54),"█","") | X54: Diferida (herramienta interna)
A55: REQ-049 | B55: P-08 | C55: Recordatorios / nudges | D55: Diferido | G55: =IF(AND($E55<>"",$F55<>"",G$4<=$F55,G$4+6>=$E55),"█","") | H55: =IF(AND($E55<>"",$F55<>"",H$4<=$F55,H$4+6>=$E55),"█","") | I55: =IF(AND($E55<>"",$F55<>"",I$4<=$F55,I$4+6>=$E55),"█","") | J55: =IF(AND($E55<>"",$F55<>"",J$4<=$F55,J$4+6>=$E55),"█","") | K55: =IF(AND($E55<>"",$F55<>"",K$4<=$F55,K$4+6>=$E55),"█","") | L55: =IF(AND($E55<>"",$F55<>"",L$4<=$F55,L$4+6>=$E55),"█","") | M55: =IF(AND($E55<>"",$F55<>"",M$4<=$F55,M$4+6>=$E55),"█","") | N55: =IF(AND($E55<>"",$F55<>"",N$4<=$F55,N$4+6>=$E55),"█","") | ... W55: =IF(AND($E55<>"",$F55<>"",W$4<=$F55,W$4+6>=$E55),"█","") | X55: Diferida; requiere plantilla HSM
A56: REQ-050 | B56: P-09 | C56: Monitoreo día D (panel) | D56: Diferido | G56: =IF(AND($E56<>"",$F56<>"",G$4<=$F56,G$4+6>=$E56),"█","") | H56: =IF(AND($E56<>"",$F56<>"",H$4<=$F56,H$4+6>=$E56),"█","") | I56: =IF(AND($E56<>"",$F56<>"",I$4<=$F56,I$4+6>=$E56),"█","") | J56: =IF(AND($E56<>"",$F56<>"",J$4<=$F56,J$4+6>=$E56),"█","") | K56: =IF(AND($E56<>"",$F56<>"",K$4<=$F56,K$4+6>=$E56),"█","") | L56: =IF(AND($E56<>"",$F56<>"",L$4<=$F56,L$4+6>=$E56),"█","") | M56: =IF(AND($E56<>"",$F56<>"",M$4<=$F56,M$4+6>=$E56),"█","") | N56: =IF(AND($E56<>"",$F56<>"",N$4<=$F56,N$4+6>=$E56),"█","") | ... W56: =IF(AND($E56<>"",$F56<>"",W$4<=$F56,W$4+6>=$E56),"█","") | X56: Panel diferido; health-check+runbook conservados
A57: REQ-051 | B57: P-11 | C57: Informe consolidado | D57: Diferido | G57: =IF(AND($E57<>"",$F57<>"",G$4<=$F57,G$4+6>=$E57),"█","") | H57: =IF(AND($E57<>"",$F57<>"",H$4<=$F57,H$4+6>=$E57),"█","") | I57: =IF(AND($E57<>"",$F57<>"",I$4<=$F57,I$4+6>=$E57),"█","") | J57: =IF(AND($E57<>"",$F57<>"",J$4<=$F57,J$4+6>=$E57),"█","") | K57: =IF(AND($E57<>"",$F57<>"",K$4<=$F57,K$4+6>=$E57),"█","") | L57: =IF(AND($E57<>"",$F57<>"",L$4<=$F57,L$4+6>=$E57),"█","") | M57: =IF(AND($E57<>"",$F57<>"",M$4<=$F57,M$4+6>=$E57),"█","") | N57: =IF(AND($E57<>"",$F57<>"",N$4<=$F57,N$4+6>=$E57),"█","") | ... W57: =IF(AND($E57<>"",$F57<>"",W$4<=$F57,W$4+6>=$E57),"█","") | X57: Diferida (deseable)

Sheet Resumen
A1: Resumen — Nuevas iniciativas (backlog T&M)
A3: Estado | B3: # Iniciativas | C3: Horas estimadas | D3: Valor estimado ($)
A4: Propuesto | B4: =COUNTIF('Nuevas iniciativas'!$F$2:$F$101,$A4) -> 12 | C4: =SUMIF('Nuevas iniciativas'!$F$2:$F$101,$A4,'Nuevas iniciativas'!$I$2:$I$101) -> 0 | D4: =SUMIF('Nuevas iniciativas'!$F$2:$F$101,$A4,'Nuevas iniciativas'!$L$2:$L$101) -> 0
A5: Estimado | B5: =COUNTIF('Nuevas iniciativas'!$F$2:$F$101,$A5) -> 0 | C5: =SUMIF('Nuevas iniciativas'!$F$2:$F$101,$A5,'Nuevas iniciativas'!$I$2:$I$101) -> 0 | D5: =SUMIF('Nuevas iniciativas'!$F$2:$F$101,$A5,'Nuevas iniciativas'!$L$2:$L$101) -> 0
A6: Aprobado | B6: =COUNTIF('Nuevas iniciativas'!$F$2:$F$101,$A6) -> 0 | C6: =SUMIF('Nuevas iniciativas'!$F$2:$F$101,$A6,'Nuevas iniciativas'!$I$2:$I$101) -> 0 | D6: =SUMIF('Nuevas iniciativas'!$F$2:$F$101,$A6,'Nuevas iniciativas'!$L$2:$L$101) -> 0
A7: En curso | B7: =COUNTIF('Nuevas iniciativas'!$F$2:$F$101,$A7) -> 3 | C7: =SUMIF('Nuevas iniciativas'!$F$2:$F$101,$A7,'Nuevas iniciativas'!$I$2:$I$101) -> 0 | D7: =SUMIF('Nuevas iniciativas'!$F$2:$F$101,$A7,'Nuevas iniciativas'!$L$2:$L$101) -> 0
A8: Entregado | B8: =COUNTIF('Nuevas iniciativas'!$F$2:$F$101,$A8) -> 25 | C8: =SUMIF('Nuevas iniciativas'!$F$2:$F$101,$A8,'Nuevas iniciativas'!$I$2:$I$101) -> 0 | D8: =SUMIF('Nuevas iniciativas'!$F$2:$F$101,$A8,'Nuevas iniciativas'!$L$2:$L$101) -> 0
A9: Facturado | B9: =COUNTIF('Nuevas iniciativas'!$F$2:$F$101,$A9) -> 0 | C9: =SUMIF('Nuevas iniciativas'!$F$2:$F$101,$A9,'Nuevas iniciativas'!$I$2:$I$101) -> 0 | D9: =SUMIF('Nuevas iniciativas'!$F$2:$F$101,$A9,'Nuevas iniciativas'!$L$2:$L$101) -> 0
A10: Cerrado | B10: =COUNTIF('Nuevas iniciativas'!$F$2:$F$101,$A10) -> 0 | C10: =SUMIF('Nuevas iniciativas'!$F$2:$F$101,$A10,'Nuevas iniciativas'!$I$2:$I$101) -> 0 | D10: =SUMIF('Nuevas iniciativas'!$F$2:$F$101,$A10,'Nuevas iniciativas'!$L$2:$L$101) -> 0
A11: TOTAL | B11: =SUM(B4:B10) -> 40 | C11: =SUM(C4:C10) -> 0 | D11: =SUM(D4:D10) -> 0
A13: Valor total a facturar ($) | B13: =SUM('Nuevas iniciativas'!$M$2:$M$101) -> 0
A15: Alcance inicial (MVP): 11 requerimientos — Cerrados y facturados (ver hoja 'Alcance inicial').

Sheet Listas
A1: Estado | B1: Tipo | C1: Prioridad
A2: Propuesto | B2: Nuevo | C2: Alta
A3: Estimado | B3: Cambio | C3: Media
A4: Aprobado | B4: Bug | C4: Baja
A5: En curso | B5: Soporte
A6: Entregado
A7: Facturado
A8: Cerrado

Sheet Estado
A1: Req | B1: ID | C1: Tipo | D1: Requerimiento | E1: Estado | F1: Detalle
A2: REQ-001 | B2: MVP base | C2: Nuevo | D2: Autenticación de administrador por OTP de WhatsApp | E2: Cerrado | F2: El administrador entra al portal sin contraseña: escribe su número y recibe un código por WhatsApp para acceder de forma segura.
A3: REQ-002 | B3: MVP base | C3: Nuevo | D3: Identidad y matrícula de participantes | E3: Cerrado | F3: El sistema reconoce a cada participante por su número de WhatsApp y solo deja participar a quienes están matriculados y activos en una campaña.
A4: REQ-003 | B4: MVP base | C4: Nuevo | D4: Gestión de campañas, usuarios y preguntas | E4: Cerrado | F4: Desde el portal se crean y editan campañas, usuarios y preguntas, y se asocian los participantes a cada campaña.
A5: REQ-004 | B5: MVP base | C5: Nuevo | D5: Envío de mensajes iniciales por WhatsApp | E5: Cerrado | F5: Permite enviar el mensaje inicial de la campaña a todos los participantes, reenviar a quienes no respondieron y reintentar los envíos fallidos.
A6: REQ-005 | B6: MVP base | C6: Nuevo | D6: Captura conversacional de ideas y consolidación | E6: Cerrado | F6: El coach por WhatsApp recibe la idea, la reformula para confirmar que la entendió y va armando la versión final sin perder lo aportado antes.
A7: REQ-006 | B7: MVP base | C7: Nuevo | D7: Rúbricas, prompts versionados y configuración LLM | E7: Cerrado | F7: El administrador carga la rúbrica de evaluación, ajusta y aprueba los textos guía y configura el modelo de IA, guardando la clave de forma segura.
A8: REQ-007 | B8: MVP base | C8: Nuevo | D8: Evaluación de ideas con LLM y retroalimentación | E8: Cerrado | F8: Cada idea confirmada se evalúa con IA según la rúbrica y devuelve una retroalimentación breve y útil, con una sola repregunta como máximo.
A9: REQ-008 | B9: MVP base | C9: Nuevo | D9: Compilación de artefactos Markdown por idea | E9: Cerrado | F9: Por cada idea se genera un documento ordenado con su evaluación, consultable desde el portal y que se puede regenerar cuando se necesite.
A10: REQ-009 | B10: MVP base | C10: Nuevo | D10: Portal administrativo Angular con marca GHT | E10: Cerrado | F10: Portal web de administración con la imagen de GHT para gestionar usuarios, campañas y configuración, y revisar los resultados de cada idea. | I10: Cerrado | J10: El requerimiento fue desarrollado, entregado, facturado y pagado
A11: REQ-011 | B11: MVP base | C11: Nuevo | D11: Plataforma base (.Azure, CI/CD) | E11: Cerrado | F11: La base técnica sobre la que corre todo: la aplicación, la base de datos, las conexiones y el despliegue automático. | I11: Desarrollado | J11: El requerimiento esta desarrollado y desplegado
A12: REQ-023 | B12: I-03 | C12: Nuevo | D12: Follow-ups al eje débil de la rúbrica | E12: Desarrollado | F12: Cuando una idea es débil en algún criterio, el coach hace una repregunta enfocada justo en ese punto para mejorarla. | I12: En pruebas | J12: El requerimietno esta desarrollado, en fase de pruebas, sin desplegar
A13: REQ-021 | B13: I-05 | C13: Nuevo | D13: Paráfrasis y transparencia | E13: Desarrollado | F13: El coach repite con sus palabras la idea de la persona para confirmar que la entendió bien, solo cuando la idea ya está madura. | I13: En curso | J13: El requerimiento está siendo desarrollado
A14: REQ-019 | B14: I-06 | C14: Nuevo | D14: Multi-idea (varias ideas por participante) | E14: Desarrollado | F14: Permite que una misma persona aporte varias ideas y que cada una se guarde y evalúe por separado. | I14: Diferido | J14: El requerimiento se encuentra a la espera de priorización y desarrollo
A15: REQ-018 | B15: I-16 | C15: Bug | D15: Fix de calificación en Markdown | E15: Desarrollado | F15: Corrige que el documento de cada idea muestre siempre la calificación más reciente, no una anterior.
A16: REQ-025 | B16: I-17 | C16: Nuevo | D16: BD de dos niveles de madurez + cierre por inactividad | E16: Desarrollado | F16: Clasifica cada idea como 'madura' o 'en incubación' según un umbral, y cierra la conversación tras un tiempo de inactividad.
A17: REQ-036 | B17: I-18 | C17: Nuevo | D17: Coaching secuencial por idea | E17: Desarrollado | F17: Cuando una persona menciona varias ideas, el coach las trabaja de a una a la vez, de forma ordenada.
A18: REQ-037 | B18: I-19 | C18: Nuevo | D18: Consolidación progresiva de ideas | E18: Desarrollado | F18: Mantiene una única versión 'oficial' de cada idea que se va completando, y evalúa siempre esa versión completa confirmada.
A19: REQ-038 | B19: I-20 | C19: Nuevo | D19: Redacción fluida + Markdown ejecutivo | E19: Desarrollado | F19: Busca que las respuestas del coach suenen naturales y que el documento de cada idea muestre su nivel y calificación de forma clara. | I19: Row Labels | J19: Count of Estado
A20: REQ-015 | B20: P-03 | C20: Soporte | D20: Reinicio de datos por participante/campaña | E20: Desarrollado | F20: Herramienta interna para borrar y reiniciar conversaciones y respuestas de un participante o de una campaña completa, conservando configuración y usuarios (útil para pruebas). | I20: Cerrado | J20: 10
A21: REQ-024 | B21: P-13 | C21: Mejora | D21: Umbral de cierre por campaña | E21: Desarrollado | F21: Permite definir, por campaña, qué tan buena debe ser una idea para darla por cerrada automáticamente. | I21: Desarrollado | J21: 15
A22: REQ-026 | B22: P-14 | C22: Nuevo | D22: Vista de solo lectura de rúbricas y prompts | E22: Desarrollado | F22: Pantalla en el portal para consultar (solo lectura) las rúbricas y los prompts configurados. | I22: Diferido | J22: 10
A23: REQ-027 | B23: P-15 | C23: Mejora | D23: Refactor del orquestador conversacional | E23: Desarrollado | F23: Mejora interna del motor de conversación para hacerlo más ordenado y mantenible, sin cambiar lo que ve el usuario. | I23: En curso | J23: 5
A24: REQ-029 | B24: P-16 | C24: Mejora | D24: Refactor de página de campañas | E24: Desarrollado | F24: Reorganiza internamente la pantalla de campañas para hacerla más mantenible, conservando su funcionamiento. | I24: En pruebas | J24: 1
A25: REQ-033 | B25: P-21 | C25: Nuevo | D25: Multi-número de WhatsApp | E25: Desarrollado | F25: Soporta varios números de WhatsApp: el sistema responde por el mismo número por el que la persona escribió. | I25: Grand Total | J25: 41
A26: REQ-040 | B26: P-25 | C26: Mejora | D26: Coaching directo sin confirmación repetitiva | E26: Desarrollado | F26: Elimina confirmaciones repetitivas: cada aporte se procesa y evalúa en el mismo momento, haciendo la conversación más ágil.
A27: REQ-020 | B27: I-09 | C27: Nuevo | D27: Tejido colectivo | E27: Diferido | F27: Conectaría las ideas de distintas personas para construir conocimiento colectivo (funcionalidad futura).
A28: REQ-044 | B28: I-10 | C28: Nuevo | D28: Flag base previa vs. en blanco | E28: Diferido | F28: Interfaz para activar el tejido colectivo eligiendo si la campaña parte de una base previa o desde cero (futuro).
A29: REQ-043 | B29: I-12 | C29: Nuevo | D29: Seed thoughts por campaña | E29: Diferido | F29: Permite cargar 'ideas semilla' por campaña para orientar y estimular los aportes de los participantes.
A30: REQ-045 | B30: P-04 | C30: Nuevo | D30: Dashboard de resultados | E30: Diferido | F30: Tablero visual con el estado y los resultados de las campañas (deseable, futuro).
A31: REQ-046 | B31: P-05 | C31: Nuevo | D31: Capa de insights | E31: Diferido | F31: Capa de análisis que extrae hallazgos y patrones de las ideas recogidas (futuro).
A32: REQ-047 | B32: P-06 | C32: Nuevo | D32: Destilación por lotes | E32: Diferido | F32: Procesa y resume grandes volúmenes de ideas por lotes (futuro).
A33: REQ-049 | B33: P-08 | C33: Nuevo | D33: Recordatorios / nudges | E33: Diferido | F33: Recordatorios automáticos a quienes no han respondido (requiere plantilla aprobada; futuro).
A34: REQ-051 | B34: P-11 | C34: Nuevo | D34: Informe consolidado | E34: Diferido | F34: Genera un informe consolidado de resultados por campaña (deseable, futuro).
A35: REQ-052 | C35: Nuevo | D35: Manuales de parametrización | E35: Diferido | F35: Documentos de funcionamiento y configuración del ssitema.
A36: REQ-053 | C36: Nuevo | D36: Multidioma | E36: Diferido | F36: Permite que el sistema interactue con el participante en el idioma almacenado en los datos de usuario.
A37: REQ-022 | B37: I-08 | C37: Nuevo | D37: Carga masiva de participantes | E37: En curso | F37: Permite cargar muchos participantes de una vez desde un archivo, con sus datos de área, empresa, etiquetas y variables demográficas.Pendiente de confirmación de campos por participante
A38: REQ-042 | B38: P-27 | C38: Mejora | D38: Clasificación de intenciones de control | E38: En curso | F38: Entiende cuando la persona quiere parar o cambiar de idea ('paremos aquí', 'pasemos a otra') y actúa en consecuencia, sin confundir esas frases con contenido de la idea. Es una combinación de deterministico y no deterministico, por lo que el comportamiento puede variar.
A39: REQ-012 | B39: P-28 | C39: Nuevo | D39: Reactivación de conversación / despertar proactivo | E39: En curso | F39: Hace que el coach responda cuando la persona escribe por su cuenta (por primera vez o tras un tiempo), saludando y ofreciéndole continuar o crear una idea, sin quedarse mudo.
A40: REQ-013 | B40: P-29 | C40: Mejora | D40: Cierre conversacional por tiempo | E40: En curso | F40: Cuando la persona deja de responder, el coach se despide de forma amable ('demos una pausa, hábleme cuando quiera') en lugar de cortar en seco, dejando la idea lista para retomar.
...
